Workbook

Sheet Model Scorecard
A1: ="Louisiana HAP Portfolio Scorecard — "&TEXT(TODAY(),"m/d/yyyy") -> Louisiana HAP Portfolio Scorecard — 8/6/2026
A2: Metric | B2: Threshold | C2: CH | D2: NZ | E2: LOM | F2: SA | G2: Severity | H2: Citation
A3: DSCR
A4: ='Dashboard Calc'!L3 -> Bridge-period DSCR | B4: ='Dashboard Calc'!M3 -> >= 1.00x | C4: ='Dashboard Calc'!N3 -> FAIL | D4: ='Dashboard Calc'!O3 -> PASS | E4: ='Dashboard Calc'!P3 -> PASS | F4: ='Dashboard Calc'!Q3 -> N/A | G4: ='Dashboard Calc'!R3 -> warning | H4: ='Dashboard Calc'!S3 -> house rule; spec Sec. 5.7
A5: ='Dashboard Calc'!L4 -> Post-resyn DSCR band (Yr2-17) | B5: ='Dashboard Calc'!M4 -> >= floor, <= ceiling | C5: ='Dashboard Calc'!N4 -> FAIL | D5: ='Dashboard Calc'!O4 -> FAIL | E5: ='Dashboard Calc'!P4 -> FAIL | F5: ='Dashboard Calc'!Q4 -> FAIL | G5: ='Dashboard Calc'!R4 -> error | H5: ='Dashboard Calc'!S4 -> QAP UW standards; register UW rules
A6: CASH FLOW & DEFERRED FEE
A7: ='Dashboard Calc'!L5 -> Deferred fee repaid <= 15 yrs | B7: ='Dashboard Calc'!M5 -> payback year <= 15 | C7: ='Dashboard Calc'!N5 -> FAIL | D7: ='Dashboard Calc'!O5 -> FAIL | E7: ='Dashboard Calc'!P5 -> FAIL | F7: ='Dashboard Calc'!Q5 -> FAIL | G7: ='Dashboard Calc'!R5 -> error | H7: ='Dashboard Calc'!S5 -> IRC Sec.42 / QAP deferred-fee standard
A8: COST, FEES & TDC
A9: ='Dashboard Calc'!L6 -> Developer fee % <= QAP cap | B9: ='Dashboard Calc'!M6 -> <= DevFeeCapPct | C9: ='Dashboard Calc'!N6 -> PASS | D9: ='Dashboard Calc'!O6 -> PASS | E9: ='Dashboard Calc'!P6 -> PASS | F9: ='Dashboard Calc'!Q6 -> PASS | G9: ='Dashboard Calc'!R6 -> error | H9: ='Dashboard Calc'!S6 -> QAP fee limits (LA 2025 — PENDING 2026)
A10: ='Dashboard Calc'!L7 -> TDC/unit vs HUD/LHC limit | B10: ='Dashboard Calc'!M7 -> <= regional limit | C10: ='Dashboard Calc'!N7 -> PASS | D10: ='Dashboard Calc'!O7 -> PASS | E10: ='Dashboard Calc'!P7 -> PASS | F10: ='Dashboard Calc'!Q7 -> PASS | G10: ='Dashboard Calc'!R7 -> error | H10: ='Dashboard Calc'!S7 -> HUD/LHC Unit TDC Limits (2024 vintage)
A11: RENTS & REHAB
A12: ='Dashboard Calc'!L8 -> Post-rehab rents <= caps | B12: ='Dashboard Calc'!M8 -> <= MIN(High HAP, 150% SAFMR) / LIHTC max | C12: ='Dashboard Calc'!N8 -> PASS | D12: ='Dashboard Calc'!O8 -> PASS | E12: ='Dashboard Calc'!P8 -> PASS | F12: ='Dashboard Calc'!Q8 -> PASS | G12: ='Dashboard Calc'!R8 -> error | H12: ='Dashboard Calc'!S8 -> Sec. 8 renewal policy / SAFMR; spec Sec. 5.2
A13: ='Dashboard Calc'!L9 -> Min rehab $/unit (IRC) | B13: ='Dashboard Calc'!M9 -> >= MinRehabIRC | C13: ='Dashboard Calc'!N9 -> PASS | D13: ='Dashboard Calc'!O9 -> PASS | E13: ='Dashboard Calc'!P9 -> PASS | F13: ='Dashboard Calc'!Q9 -> PASS | G13: ='Dashboard Calc'!R9 -> error | H13: ='Dashboard Calc'!S9 -> IRC Sec.42(e)(3)(A)(ii) — indexed min PLACEHOLDER
A14: ='Dashboard Calc'!L10 -> Min rehab $/unit (LA QAP) | B14: ='Dashboard Calc'!M10 -> 2026 QAP value unconfirmed | C14: ='Dashboard Calc'!N10 -> PENDING | D14: ='Dashboard Calc'!O10 -> PENDING | E14: ='Dashboard Calc'!P10 -> PENDING | F14: ='Dashboard Calc'!Q10 -> PENDING | G14: ='Dashboard Calc'!R10 -> warning | H14: ='Dashboard Calc'!S10 -> LA QAP rehab standard — PENDING
A15: CREDIT STRUCTURE & SIZING
A16: ='Dashboard Calc'!L11 -> Tax-exempt bond test | B16: ='Dashboard Calc'!M11 -> >= 25% of aggregate basis (OBBBA) | C16: ='Dashboard Calc'!N11 -> PASS | D16: ='Dashboard Calc'!O11 -> PASS | E16: ='Dashboard Calc'!P11 -> PASS | F16: ='Dashboard Calc'!Q11 -> PASS | G16: ='Dashboard Calc'!R11 -> error | H16: ='Dashboard Calc'!S11 -> IRC Sec.42(h)(4) as amended (OBBBA P.L. 119-21)
A17: ='Dashboard Calc'!L15 -> Sources = Uses w/o unfunded soft gap | B17: ='Dashboard Calc'!M15 -> required soft funds = 0 | C17: ='Dashboard Calc'!N15 -> FAIL | D17: ='Dashboard Calc'!O15 -> FAIL | E17: ='Dashboard Calc'!P15 -> PASS | F17: ='Dashboard Calc'!Q15 -> PASS | G17: ='Dashboard Calc'!R15 -> error | H17: ='Dashboard Calc'!S15 -> arithmetic check; spec Sec. 9.5
A18: OPERATING & PRICING
A19: ='Dashboard Calc'!L12 -> Underwritten vacancy floor | B19: ='Dashboard Calc'!M12 -> >= VacancyMin | C19: ='Dashboard Calc'!N12 -> FAIL | D19: ='Dashboard Calc'!O12 -> FAIL | E19: ='Dashboard Calc'!P12 -> PASS | F19: ='Dashboard Calc'!Q12 -> PASS | G19: ='Dashboard Calc'!R12 -> warning | H19: ='Dashboard Calc'!S12 -> QAP UW standards
A20: ='Dashboard Calc'!L13 -> Expense PUPA floor | B20: ='Dashboard Calc'!M13 -> >= OpexMinPU | C20: ='Dashboard Calc'!N13 -> PASS | D20: ='Dashboard Calc'!O13 -> PASS | E20: ='Dashboard Calc'!P13 -> PASS | F20: ='Dashboard Calc'!Q13 -> PASS | G20: ='Dashboard Calc'!R13 -> warning | H20: ='Dashboard Calc'!S13 -> QAP UW standards
A21: ='Dashboard Calc'!L14 -> Solved price/unit vs OM comps | B21: ='Dashboard Calc'!M14 -> sanity: <= comp wtd avg | C21: ='Dashboard Calc'!N14 -> REVIEW | D21: ='Dashboard Calc'!O14 -> REVIEW | E21: ='Dashboard Calc'!P14 -> PASS | F21: ='Dashboard Calc'!Q14 -> PASS | G21: ='Dashboard Calc'!R14 -> info | H21: ='Dashboard Calc'!S14 -> OM sale comps pp.11/18/25/32 (market-rate sales)
A22: PENDING ITEMS
A23: ='Dashboard Calc'!L16 -> URA applicability | B23: ='Dashboard Calc'!M16 -> funding stack final? | C23: ='Dashboard Calc'!N16 -> PENDING | D23: ='Dashboard Calc'!O16 -> PENDING | E23: ='Dashboard Calc'!P16 -> PENDING | F23: ='Dashboard Calc'!Q16 -> PENDING | G23: ='Dashboard Calc'!R16 -> warning | H23: ='Dashboard Calc'!S16 -> 49 CFR Part 24; NZ HOME loan in existing stack
A24: ='Dashboard Calc'!L17 -> QAP vintage (2026 confirm) | B24: ='Dashboard Calc'!M17 -> register = LA 2025 QAP | C24: ='Dashboard Calc'!N17 -> PENDING | D24: ='Dashboard Calc'!O17 -> PENDING | E24: ='Dashboard Calc'!P17 -> PENDING | F24: ='Dashboard Calc'!Q17 -> PENDING | G24: ='Dashboard Calc'!R17 -> warning | H24: ='Dashboard Calc'!S17 -> spec Gap #6
A26: VERDICT (per property) | C26: ='Dashboard Calc'!N22 -> FAIL | D26: ='Dashboard Calc'!O22 -> FAIL | E26: ='Dashboard Calc'!P22 -> FAIL | F26: ='Dashboard Calc'!Q22 -> FAIL
A27: PORTFOLIO VERDICT | C27: ='Dashboard Calc'!N23 -> FAIL

Sheet Dashboard Calc
A1: DASHBOARD CALC — DEAL INPUTS & KPI ENGINE | J1: KPI RULE REGISTER (per-property status engine — Scorecard pulls from here)
B2: Deal Inputs | C2: Clear Horizons | D2: New Zion | E2: Live Oak Manor | F2: Spanish Arms | G2: Portfolio | J2: # | K2: kpi_id | L2: metric | M2: threshold | N2: CH | O2: NZ | P2: LOM | Q2: SA | R2: severity | S2: citation
B3: Property Name | C3: Clear Horizons | D3: New Zion | E3: Live Oak Manor | F3: Spanish Arms | J3: 1 | K3: UW-DSCR-BRIDGE | L3: Bridge-period DSCR | M3: >= 1.00x | N3: =IF(CH_BridgeDSCR="n/a","N/A",IF(CH_BridgeDSCR>=1,"PASS","FAIL")) -> FAIL | O3: =IF(NZ_BridgeDSCR="n/a","N/A",IF(NZ_BridgeDSCR>=1,"PASS","FAIL")) -> PASS | P3: =IF(LOM_BridgeDSCR="n/a","N/A",IF(LOM_BridgeDSCR>=1,"PASS","FAIL")) -> PASS | Q3: =IF(SA_BridgeDSCR="n/a","N/A",IF(SA_BridgeDSCR>=1,"PASS","FAIL")) -> N/A | R3: warning | S3: house rule; spec Sec. 5.7
B4: Units | C4: 84 | D4: 100 | E4: 119 | F4: 204 | G4: =SUM(C4:F4) -> 507 | J4: 2 | K4: UW-DSCR-BAND | L4: Post-resyn DSCR band (Yr2-17) | M4: >= floor, <= ceiling | N4: =IF(AND(MIN('CH - Pro Forma'!$E$39:$S$39)>=DSCRFloor,MAX('CH - Pro Forma'!$E$39:$S$39)<=DSCRCeil),"PASS","FAIL") -> FAIL | O4: =IF(AND(MIN('NZ - Pro Forma'!$E$39:$S$39)>=DSCRFloor,MAX('NZ - Pro Forma'!$E$39:$S$39)<=DSCRCeil),"PASS","FAIL") -> FAIL | P4: =IF(AND(MIN('LOM - Pro Forma'!$E$39:$S$39)>=DSCRFloor,MAX('LOM - Pro Forma'!$E$39:$S$39)<=DSCRCeil),"PASS","FAIL") -> FAIL | Q4: =IF(AND(MIN('SA - Pro Forma'!$E$39:$S$39)>=DSCRFloor,MAX('SA - Pro Forma'!$E$39:$S$39)<=DSCRCeil),"PASS","FAIL") -> FAIL | R4: error | S4: QAP UW standards; register UW rules
B5: HAP Units | C5: 84 | D5: 100 | E5: 119 | F5: 123 | G5: =SUM(C5:F5) -> 426 | J5: 3 | K5: UW-DDF-15YR | L5: Deferred fee repaid <= 15 yrs | M5: payback year <= 15 | N5: =IF(CH_DDF=0,"N/A",IF(ISNUMBER(CH_DDFPayback),IF(CH_DDFPayback<=15,"PASS","FAIL"),"FAIL")) -> FAIL | O5: =IF(NZ_DDF=0,"N/A",IF(ISNUMBER(NZ_DDFPayback),IF(NZ_DDFPayback<=15,"PASS","FAIL"),"FAIL")) -> FAIL | P5: =IF(LOM_DDF=0,"N/A",IF(ISNUMBER(LOM_DDFPayback),IF(LOM_DDFPayback<=15,"PASS","FAIL"),"FAIL")) -> FAIL | Q5: =IF(SA_DDF=0,"N/A",IF(ISNUMBER(SA_DDFPayback),IF(SA_DDFPayback<=15,"PASS","FAIL"),"FAIL")) -> FAIL | R5: error | S5: IRC Sec.42 / QAP deferred-fee standard
B6: Net Rentable SF | C6: 73816 | D6: 71212 | E6: 102104 | F6: 191932 | G6: =SUM(C6:F6) -> 439064 | J6: 4 | K6: FEE-DEV-PCT | L6: Developer fee % <= QAP cap | M6: <= DevFeeCapPct | N6: =IF('Sources & Uses'!C25<=DevFeeCapPct,"PASS","FAIL") -> PASS | O6: =IF('Sources & Uses'!D25<=DevFeeCapPct,"PASS","FAIL") -> PASS | P6: =IF('Sources & Uses'!E25<=DevFeeCapPct,"PASS","FAIL") -> PASS | Q6: =IF('Sources & Uses'!F25<=DevFeeCapPct,"PASS","FAIL") -> PASS | R6: error | S6: QAP fee limits (LA 2025 — PENDING 2026)
B7: Parish | C7: Caddo | D7: Caddo | E7: Vermilion | F7: E. Baton Rouge | J7: 5 | K7: UW-TDC | L7: TDC/unit vs HUD/LHC limit | M7: <= regional limit | N7: =IF(CH_TDCpu<=CH_TDCLimitPU,"PASS","FAIL") -> PASS | O7: =IF(NZ_TDCpu<=NZ_TDCLimitPU,"PASS","FAIL") -> PASS | P7: =IF(LOM_TDCpu<=LOM_TDCLimitPU,"PASS","FAIL") -> PASS | Q7: =IF(SA_TDCpu<=SA_TDCLimitPU,"PASS","FAIL") -> PASS | R7: error | S7: HUD/LHC Unit TDC Limits (2024 vintage)
B8: TDC Region | C8: Shreveport | D8: Shreveport | E8: Lafayette | F8: Baton Rouge | J8: 6 | K8: UW-RENT-CAP | L8: Post-rehab rents <= caps | M8: <= MIN(High HAP, 150% SAFMR) / LIHTC max | N8: =IF(COUNTIF(CH_CapCheck,"FAIL")=0,"PASS","FAIL") -> PASS | O8: =IF(COUNTIF(NZ_CapCheck,"FAIL")=0,"PASS","FAIL") -> PASS | P8: =IF(COUNTIF(LOM_CapCheck,"FAIL")=0,"PASS","FAIL") -> PASS | Q8: =IF(COUNTIF(SA_CapCheck,"FAIL")=0,"PASS","FAIL") -> PASS | R8: error | S8: Sec. 8 renewal policy / SAFMR; spec Sec. 5.2
B9: Building Type | C9: Walkup | D9: Walkup | E9: Walkup | F9: Walkup | J9: 7 | K9: UW-MINREHAB-IRC | L9: Min rehab $/unit (IRC) | M9: >= MinRehabIRC | N9: =IF('Rehab Scope'!C9>=MinRehabIRC,"PASS","FAIL") -> PASS | O9: =IF('Rehab Scope'!D9>=MinRehabIRC,"PASS","FAIL") -> PASS | P9: =IF('Rehab Scope'!E9>=MinRehabIRC,"PASS","FAIL") -> PASS | Q9: =IF('Rehab Scope'!F9>=MinRehabIRC,"PASS","FAIL") -> PASS | R9: error | S9: IRC Sec.42(e)(3)(A)(ii) — indexed min PLACEHOLDER
B10: Credit Type | C10: 4% bond | D10: 4% bond | E10: 4% bond | F10: 4% bond | J10: 8 | K10: UW-MINREHAB-QAP | L10: Min rehab $/unit (LA QAP) | M10: 2026 QAP value unconfirmed | N10: =IF(MinRehabQAP="","PENDING",IF('Rehab Scope'!C9>=MinRehabQAP,"PASS","FAIL")) -> PENDING | O10: =IF(MinRehabQAP="","PENDING",IF('Rehab Scope'!D9>=MinRehabQAP,"PASS","FAIL")) -> PENDING | P10: =IF(MinRehabQAP="","PENDING",IF('Rehab Scope'!E9>=MinRehabQAP,"PASS","FAIL")) -> PENDING | Q10: =IF(MinRehabQAP="","PENDING",IF('Rehab Scope'!F9>=MinRehabQAP,"PASS","FAIL")) -> PENDING | R10: warning | S10: LA QAP rehab standard — PENDING
B11: Basis Boost Eligible | C11: Yes | D11: Yes | E11: Yes | F11: Yes | J11: 9 | K11: ELG-BOND-25 | L11: Tax-exempt bond test | M11: >= 25% of aggregate basis (OBBBA) | N11: =CH_BondTest -> PASS | O11: =NZ_BondTest -> PASS | P11: =LOM_BondTest -> PASS | Q11: =SA_BondTest -> PASS | R11: error | S11: IRC Sec.42(h)(4) as amended (OBBBA P.L. 119-21)
B12: Acquisition Price | C12: 0 | D12: 0 | E12: 3000000 | F12: 500000 | G12: =SUM(C12:F12) -> 3500000 | J12: 10 | K12: UW-VAC-MIN | L12: Underwritten vacancy floor | M12: >= VacancyMin | N12: =IF(CH_VacHAP>=VacancyMin,"PASS","FAIL") -> FAIL | O12: =IF(NZ_VacHAP>=VacancyMin,"PASS","FAIL") -> FAIL | P12: =IF(LOM_VacHAP>=VacancyMin,"PASS","FAIL") -> PASS | Q12: =IF(SA_VacHAP>=VacancyMin,"PASS","FAIL") -> PASS | R12: warning | S12: QAP UW standards
B13: Land % of Acq Price | C13: 0.15 | D13: 0.15 | E13: 0.15 | F13: 0.15 | J13: 11 | K13: UW-OPEX-MIN | L13: Expense PUPA floor | M13: >= OpexMinPU | N13: =IF('Rev+Expenses'!C34>=OpexMinPU,"PASS","FAIL") -> PASS | O13: =IF('Rev+Expenses'!D34>=OpexMinPU,"PASS","FAIL") -> PASS | P13: =IF('Rev+Expenses'!E34>=OpexMinPU,"PASS","FAIL") -> PASS | Q13: =IF('Rev+Expenses'!F34>=OpexMinPU,"PASS","FAIL") -> PASS | R13: warning | S13: QAP UW standards
B14: Acquisition Date | C14: 46357 | D14: 46357 | E14: 46357 | F14: 46357 | J14: 12 | K14: UW-PRICE-COMP | L14: Solved price/unit vs OM comps | M14: sanity: <= comp wtd avg | N14: =IF(CH_MaxPrice=0,"REVIEW",IF(CH_MaxPrice/CH_Units<=60000,"PASS","REVIEW")) -> REVIEW | O14: =IF(NZ_MaxPrice=0,"REVIEW",IF(NZ_MaxPrice/NZ_Units<=60000,"PASS","REVIEW")) -> REVIEW | P14: =IF(LOM_MaxPrice=0,"REVIEW",IF(LOM_MaxPrice/LOM_Units<=60000,"PASS","REVIEW")) -> PASS | Q14: =IF(SA_MaxPrice=0,"REVIEW",IF(SA_MaxPrice/SA_Units<=60000,"PASS","REVIEW")) -> PASS | R14: info | S14: OM sale comps pp.11/18/25/32 (market-rate sales)
B15: Resyndication Close Date | C15: 46753 | D15: 47119 | E15: 47119 | F15: 46357 | J15: 13 | K15: UW-SU-BAL | L15: Sources = Uses w/o unfunded soft gap | M15: required soft funds = 0 | N15: =IF('Sources & Uses'!C12<=SUBalanceTol,"PASS","FAIL") -> FAIL | O15: =IF('Sources & Uses'!D12<=SUBalanceTol,"PASS","FAIL") -> FAIL | P15: =IF('Sources & Uses'!E12<=SUBalanceTol,"PASS","FAIL") -> PASS | Q15: =IF('Sources & Uses'!F12<=SUBalanceTol,"PASS","FAIL") -> PASS | R15: error | S15: arithmetic check; spec Sec. 9.5
B16: Bridge Period (months) | C16: =DATEDIF(C14,C15,"m") -> 13 | D16: =DATEDIF(D14,D15,"m") -> 25 | E16: =DATEDIF(E14,E15,"m") -> 25 | F16: =DATEDIF(F14,F15,"m") -> 0 | J16: 14 | K16: UW-URA | L16: URA applicability | M16: funding stack final? | N16: ="PENDING" -> PENDING | O16: ="PENDING" -> PENDING | P16: ="PENDING" -> PENDING | Q16: ="PENDING" -> PENDING | R16: warning | S16: 49 CFR Part 24; NZ HOME loan in existing stack
B17: Rehab Duration (months) | C17: 12 | D17: 12 | E17: 15 | F17: 18 | J17: 15 | K17: UW-QAP-VINTAGE | L17: QAP vintage (2026 confirm) | M17: register = LA 2025 QAP | N17: ="PENDING" -> PENDING | O17: ="PENDING" -> PENDING | P17: ="PENDING" -> PENDING | Q17: ="PENDING" -> PENDING | R17: warning | S17: spec Gap #6
B18: Hold Period End | C18: 53692 | D18: 53692 | E18: 53692 | F18: 53692
B19: Vintage Inflation Years | C19: =YEAR(C15)-YEAR($C$14) -> 2 | D19: =YEAR(D15)-YEAR($C$14) -> 3 | E19: =YEAR(E15)-YEAR($C$14) -> 3 | F19: =YEAR(F15)-YEAR($C$14) -> 0 | J19: Hard fails | N19: =COUNTIFS($R$3:$R$17,"error",N$3:N$17,"FAIL") -> 3 | O19: =COUNTIFS($R$3:$R$17,"error",O$3:O$17,"FAIL") -> 3 | P19: =COUNTIFS($R$3:$R$17,"error",P$3:P$17,"FAIL") -> 2 | Q19: =COUNTIFS($R$3:$R$17,"error",Q$3:Q$17,"FAIL") -> 2
J20: Warnings failing | N20: =COUNTIFS($R$3:$R$17,"warning",N$3:N$17,"FAIL") -> 2 | O20: =COUNTIFS($R$3:$R$17,"warning",O$3:O$17,"FAIL") -> 1 | P20: =COUNTIFS($R$3:$R$17,"warning",P$3:P$17,"FAIL") -> 0 | Q20: =COUNTIFS($R$3:$R$17,"warning",Q$3:Q$17,"FAIL") -> 0
B21: Global Assumptions | C21: Value | J21: Pending | N21: =COUNTIF(N$3:N$17,"PENDING") -> 3 | O21: =COUNTIF(O$3:O$17,"PENDING") -> 3 | P21: =COUNTIF(P$3:P$17,"PENDING") -> 3 | Q21: =COUNTIF(Q$3:Q$17,"PENDING") -> 3
B22: Target Return Metric | C22: DSCR-constrained | J22: VERDICT | N22: =IF(N19>0,"FAIL",IF((N20+N21)>0,"MARGINAL","PENCILS")) -> FAIL | O22: =IF(O19>0,"FAIL",IF((O20+O21)>0,"MARGINAL","PENCILS")) -> FAIL | P22: =IF(P19>0,"FAIL",IF((P20+P21)>0,"MARGINAL","PENCILS")) -> FAIL | Q22: =IF(Q19>0,"FAIL",IF((Q20+Q21)>0,"MARGINAL","PENCILS")) -> FAIL
B23: Solver DSCR Floor | C23: 1.15 | J23: PORTFOLIO VERDICT | N23: =IF(COUNTIF(N22:Q22,"FAIL")>0,"FAIL",IF(COUNTIF(N22:Q22,"MARGINAL")>0,"MARGINAL","PENCILS")) -> FAIL
B24: OCAF / HAP Rent Growth | C24: 0.025
B25: OCAF Achievement Haircut | C25: 0.75
B26: First-Year LA OCAF (2027) | C26: 0.098
B27: Expense Growth | C27: 0.03
B28: Insurance Growth | C28: 0.06
B29: Post-Rehab Rent Uplift | C29: 0.1
B30: Cost Inflation (vintage $) | C30: 0.04
B31: 4% LIHTC Equity Price | C31: 0.8
B32: Perm Debt Rate (refi) | C32: 0.06
B33: Perm Amortization (yrs) | C33: 35
B34: Perm LTV Cap | C34: 0.9
B35: Debt Strategy (base case) | C35: Refinance
B36: Rehab Hard Cost $/Unit | C36: 40000
B37: Tenant Relocation $/Unit | C37: 2500
B38: Management Fee % | C38: 0.04
B39: SA HAP Renewal (post-4/30/30) | C39: Renew + OCAF trend
B41: KPI register (columns J+) is built with the Model Scorecard step.

Sheet OM Actuals
A1: OM ACTUALS — STATIC REFERENCE DUMP (SVN Offering Memorandum)
B2: Published OM figures only. Per Sec. 9.2 hierarchy, executed DD documents override the OM; variances found in diligence are recorded in the VARIANCE NOTES block at the bottom of this sheet.
B4: CLEAR HORIZONS — INCOME & EXPENSES (OM p.9) | C4: 2024 Audit | D4: 2025 Audit | E4: 2026 Budget | F4: OM Current Rents* | G4: OM Post-Rehab*
B5: Rental Revenue | C5: 882240 | D5: 924973 | E5: 977289 | F5: 1041024 | G5: 1145126
B6: Vacancies & Rent Concessions | C6: -130117 | D6: -76791 | E6: -61743 | F6: -52051 | G6: -57256
B7: Financial Revenue | C7: 1419 | D7: 611 | E7: 0 | F7: 0 | G7: 0
B8: Other Revenue | C8: 9732 | D8: 16458 | E8: 15348 | F8: 13095 | G8: 13095
B9: Total Income | C9: 763274 | D9: 865251 | E9: 930894 | F9: 1002068 | G9: 1100965
B10: Administrative Expenses | C10: 190634 | D10: 233628 | E10: 225894 | F10: 194189 | G10: 201268
B11: Utilities Expense | C11: 105165 | D11: 119952 | E11: 129702 | F11: 129702 | G11: 129702
B12: Operating & Maintenance Expenses | C12: 521839 | D12: 538847 | E12: 428546 | F12: 329597 | G12: 329597
B13: Taxes & Insurance Expenses | C13: 156161 | D13: 158657 | E13: 154121 | F13: 149893 | G13: 149893
B14: Reserves | C14: 18936 | D14: 18937 | E14: 18937 | F14: 25200 | G14: 25200
B15: Gross Expenses | C15: 992735 | D15: 1070021 | E15: 957200 | F15: 828581 | G15: 835660
B16: Net Operating Income | C16: -229461 | D16: -204770 | E16: -26306 | F16: 173487 | G16: 265305
B19: NEW ZION — INCOME & EXPENSES (OM p.16) | C19: 2024 Audit | D19: 2025 Audit | E19: 2026 Budget | F19: OM Current Rents* | G19: OM Post-Rehab*
B20: Rental Revenue | C20: 1055452 | D20: 1088020 | E20: 1127028 | F20: 1250739 | G20: 1375813
B21: Vacancies & Rent Concessions | C21: -152508 | D21: -76003 | E21: -60328 | F21: -62537 | G21: -68791
B22: Financial Revenue | C22: 3296 | D22: 1918 | E22: 0 | F22: 0 | G22: 0
B23: Other Revenue | C23: 10518 | D23: 12095 | E23: 8040 | F23: 11307 | G23: 11307
B24: Total Income | C24: 916758 | D24: 1026030 | E24: 1074740 | F24: 1199509 | G24: 1318329
B25: Administrative Expenses | C25: 245612 | D25: 286194 | E25: 249338 | F25: 216454 | G25: 224959
B26: Utilities Expense | C26: 69411 | D26: 65311 | E26: 66614 | F26: 66614 | G26: 66614
B27: Operating & Maintenance Expenses | C27: 517638 | D27: 511923 | E27: 435741 | F27: 366083 | G27: 366083
B28: Taxes & Insurance Expenses | C28: 184343 | D28: 169930 | E28: 163199 | F28: 157724 | G28: 157724
B29: Reserves | C29: 30480 | D29: 30480 | E29: 30480 | F29: 30000 | G29: 30000
B30: Gross Expenses | C30: 1047484 | D30: 1063838 | E30: 945372 | F30: 836876 | G30: 845381
B31: Net Operating Income | C31: -130726 | D31: -37808 | E31: 129368 | F31: 362633 | G31: 472948
B34: LIVE OAK MANOR — INCOME & EXPENSES (OM p.23) | C34: 2024 Audit | D34: 2025 Audit | E34: 2026 Budget | F34: OM Current Rents* | G34: OM Post-Rehab*
B35: Rental Revenue | C35: 1370464 | D35: 1427333 | E35: 1481844 | F35: 1569468 | G35: 1726415
B36: Vacancies & Rent Concessions | C36: -97424 | D36: -104704 | E36: -60314 | F36: -78473 | G36: -86321
B37: Financial Revenue | C37: 12138 | D37: 1813 | E37: 0 | F37: 0 | G37: 0
B38: Other Revenue | C38: 45461 | D38: 20035 | E38: 18452 | F38: 16003 | G38: 16003
B39: Total Income | C39: 1330639 | D39: 1344477 | E39: 1439982 | F39: 1506998 | G39: 1656097
B40: Administrative Expenses | C40: 266965 | D40: 232329 | E40: 254608 | F40: 220490 | G40: 229593
B41: Utilities Expense | C41: 102940 | D41: 113781 | E41: 122995 | F41: 122995 | G41: 122995
B42: Operating & Maintenance Expenses | C42: 421527 | D42: 494756 | E42: 478216 | F42: 374748 | G42: 374748
B43: Taxes & Insurance Expenses | C43: 330926 | D43: 234200 | E43: 238239 | F43: 215821 | G43: 215821
B44: Reserves | C44: 11589 | D44: 11652 | E44: 11652 | F44: 35700 | G44: 35700
B45: Gross Expenses | C45: 1133947 | D45: 1086718 | E45: 1105710 | F45: 969754 | G45: 978857
...

Sheet Unit Mix+Rents
A1: UNIT MIX + RENTS — HAP RENT ARCHITECTURE
B2: Five rent tiers per unit type (spec Sec. 5.2): current HAP rent (HUD schedule) -> OCAF-trended to resyndication close -> post-rehab (uplift) vs High HAP comp and 150% SAFMR ceilings. Spanish Arms adds the 2026 LIHTC Max column governing its non-HAP units. DD rent schedules govern over OM (Sec. 9.2).
B4: CLEAR HORIZONS — resyndication close: | E4: =CH_ResynDate -> 46753 | G4: (OM p.10)
B5: HUD Rent Schedule effective | C5: 46204 | E5: Year-1 OCAF (published) | G5: =OCAF -> 0.025 | H5: OCAF bumps to close | J5: =ROUNDDOWN(YEARFRAC($C$5,CH_ResynDate),0) -> 1 | K5: Trend factor | M5: =IF($J$5<=0,1,(1+$G$5*OCAFHaircut)*(1+OCAF*OCAFHaircut)^($J$5-1)) -> 1.01875
B6: Unit Type | C6: Count | D6: SF | E6: Current Rent | F6: UA | G6: OCAF-Trended | H6: Post-Rehab | I6: High HAP | J6: 150% SAFMR | K6: LIHTC Max '26 | L6: Cap Check | M6: In-Place 4/26 | N6: Tier
B7: 1BR/1BA - HAP | C7: 8 | D7: 682 | E7: 885 | F7: 127 | G7: =E7*$M$5 -> 901.59375 | H7: =G7*(1+PostRehabUplift) -> 991.75312 | I7: 1088 | J7: 1223 | L7: =IF(H7<=MIN(I7,J7),"PASS","FAIL") -> PASS | M7: 814 | N7: HAP
B8: 2BR/1BA - HAP | C8: 32 | D8: 750 | E8: 961 | F8: 107 | G8: =E8*$M$5 -> 979.01875 | H8: =G8*(1+PostRehabUplift) -> 1076.9206 | I8: 1216 | J8: 1423 | L8: =IF(H8<=MIN(I8,J8),"PASS","FAIL") -> PASS | M8: 884 | N8: HAP
B9: 3BR/1BA - HAP | C9: 4 | D9: 990 | E9: 1100 | F9: 153 | G9: =E9*$M$5 -> 1120.625 | H9: =G9*(1+PostRehabUplift) -> 1232.6875 | I9: 1422 | J9: 1857 | L9: =IF(H9<=MIN(I9,J9),"PASS","FAIL") -> PASS | M9: 1012 | N9: HAP
B10: 3BR/1.5BA - HAP | C10: 40 | D10: 1010 | E10: 1113 | F10: 149 | G10: =E10*$M$5 -> 1133.8688 | H10: =G10*(1+PostRehabUplift) -> 1247.2556 | I10: 1422 | J10: 1861 | L10: =IF(H10<=MIN(I10,J10),"PASS","FAIL") -> PASS | M10: 1024 | N10: HAP
B11: TOTALS / MONTHLY | C11: =SUM(C7:C10) -> 84 | D11: =SUMPRODUCT(C7:C10,D7:D10) -> 73816 | E11: =SUMPRODUCT($C7:$C10,E7:E10) -> 86752 | G11: =SUMPRODUCT($C7:$C10,G7:G10) -> 88378.6 | H11: =SUMPRODUCT($C7:$C10,H7:H10) -> 97216.46 | L11: =IF(COUNTIF(L7:L10,"FAIL")=0,"PASS",COUNTIF(L7:L10,"FAIL")&" FAIL") -> PASS | M11: =SUMPRODUCT($C7:$C10,M7:M10) -> 79808
B12: Units check vs Dashboard | C12: =IF(C11=CH_Units,"OK","MISMATCH") -> OK
B14: NEW ZION — resyndication close: | E14: =NZ_ResynDate -> 47119 | G14: (OM p.17)
B15: HUD Rent Schedule effective | C15: 46023 | E15: Year-1 OCAF (published) | G15: 0.098 | H15: OCAF bumps to close | J15: =ROUNDDOWN(YEARFRAC($C$15,NZ_ResynDate),0) -> 3 | K15: Trend factor | M15: =IF($J$15<=0,1,(1+$G$15*OCAFHaircut)*(1+OCAF*OCAFHaircut)^($J$15-1)) -> 1.1141337
B16: Unit Type | C16: Count | D16: SF | E16: Current Rent | F16: UA | G16: OCAF-Trended | H16: Post-Rehab | I16: High HAP | J16: 150% SAFMR | K16: LIHTC Max '26 | L16: Cap Check | M16: In-Place 4/26 | N16: Tier
B17: 1BR/1BA - HAP | C17: 12 | D17: 529 | E17: 875 | F17: 101 | G17: =E17*$M$15 -> 974.86695 | H17: =G17*(1+PostRehabUplift) -> 1072.3536 | I17: 1088 | J17: 1249 | L17: =IF(H17<=MIN(I17,J17),"PASS","FAIL") -> PASS | M17: 875 | N17: HAP
B18: 2BR/1BA - HAP | C18: 64 | D18: 676 | E18: 924 | F18: 109 | G18: =E18*$M$15 -> 1029.4595 | H18: =G18*(1+PostRehabUplift) -> 1132.4054 | I18: 1216 | J18: 1421 | L18: =IF(H18<=MIN(I18,J18),"PASS","FAIL") -> PASS | M18: 924 | N18: HAP
B19: 3BR/1BA - HAP | C19: 24 | D19: 900 | E19: 1144 | F19: 128 | G19: =E19*$M$15 -> 1274.5689 | H19: =G19*(1+PostRehabUplift) -> 1402.0258 | I19: 1422 | J19: 1882 | L19: =IF(H19<=MIN(I19,J19),"PASS","FAIL") -> PASS | M19: 1144 | N19: HAP
B20: TOTALS / MONTHLY | C20: =SUM(C17:C19) -> 100 | D20: =SUMPRODUCT(C17:C19,D17:D19) -> 71212 | E20: =SUMPRODUCT($C17:$C19,E17:E19) -> 97092 | G20: =SUMPRODUCT($C17:$C19,G17:G19) -> 108173.46 | H20: =SUMPRODUCT($C17:$C19,H17:H19) -> 118990.81 | L20: =IF(COUNTIF(L17:L19,"FAIL")=0,"PASS",COUNTIF(L17:L19,"FAIL")&" FAIL") -> PASS | M20: =SUMPRODUCT($C17:$C19,M17:M19) -> 97092
B21: Units check vs Dashboard | C21: =IF(C20=NZ_Units,"OK","MISMATCH") -> OK
B23: LIVE OAK MANOR — resyndication close: | E23: =LOM_ResynDate -> 47119 | G23: (OM p.24)
B24: HUD Rent Schedule effective | C24: 46113 | E24: Year-1 OCAF (published) | G24: =OCAF -> 0.025 | H24: OCAF bumps to close | J24: =ROUNDDOWN(YEARFRAC($C$24,LOM_ResynDate),0) -> 2 | K24: Trend factor | M24: =IF($J$24<=0,1,(1+$G$24*OCAFHaircut)*(1+OCAF*OCAFHaircut)^($J$24-1)) -> 1.0378516
B25: Unit Type | C25: Count | D25: SF | E25: Current Rent | F25: UA | G25: OCAF-Trended | H25: Post-Rehab | I25: High HAP | J25: 150% SAFMR | K25: LIHTC Max '26 | L25: Cap Check | M25: In-Place 4/26 | N25: Tier
B26: 2BR/1BA - HAP | C26: 19 | D26: 716 | E26: 931 | F26: 71 | G26: =E26*$M$24 -> 966.2398 | H26: =G26*(1+PostRehabUplift) -> 1062.8638 | I26: 1065 | J26: 1204 | L26: =IF(H26<=MIN(I26,J26),"PASS","FAIL") -> PASS | M26: 864 | N26: HAP
B27: 3BR/1BA - HAP | C27: 50 | D27: 822 | E27: 1060 | F27: 96 | G27: =E27*$M$24 -> 1100.1227 | H27: =G27*(1+PostRehabUplift) -> 1210.1349 | I27: 1326 | J27: 1584 | L27: =IF(H27<=MIN(I27,J27),"PASS","FAIL") -> PASS | M27: 984 | N27: HAP
B28: 4BR/1BA - HAP | C28: 50 | D28: 948 | E28: 1202 | F28: 108 | G28: =E28*$M$24 -> 1247.4976 | H28: =G28*(1+PostRehabUplift) -> 1372.2473 | I28: 1404 | J28: 1587 | L28: =IF(H28<=MIN(I28,J28),"PASS","FAIL") -> PASS | M28: 1116 | N28: HAP
B29: TOTALS / MONTHLY | C29: =SUM(C26:C28) -> 119 | D29: =SUMPRODUCT(C26:C28,D26:D28) -> 102104 | E29: =SUMPRODUCT($C26:$C28,E26:E28) -> 130789 | G29: =SUMPRODUCT($C26:$C28,G26:G28) -> 135739.57 | H29: =SUMPRODUCT($C26:$C28,H26:H28) -> 149313.52 | L29: =IF(COUNTIF(L26:L28,"FAIL")=0,"PASS",COUNTIF(L26:L28,"FAIL")&" FAIL") -> PASS | M29: =SUMPRODUCT($C26:$C28,M26:M28) -> 121416
B30: Units check vs Dashboard | C30: =IF(C29=LOM_Units,"OK","MISMATCH") -> OK
B32: SPANISH ARMS — resyndication close: | E32: =SA_ResynDate -> 46357 | G32: (OM p.31)
B33: HUD Rent Schedule effective | C33: 46143 | E33: Year-1 OCAF (published) | G33: =OCAF -> 0.025 | H33: OCAF bumps to close | J33: =ROUNDDOWN(YEARFRAC($C$33,SA_ResynDate),0) -> 0 | K33: Trend factor | M33: =IF($J$33<=0,1,(1+$G$33*OCAFHaircut)*(1+OCAF*OCAFHaircut)^($J$33-1)) -> 1
B34: Unit Type | C34: Count | D34: SF | E34: Current Rent | F34: UA | G34: OCAF-Trended | H34: Post-Rehab | I34: High HAP | J34: 150% SAFMR | K34: LIHTC Max '26 | L34: Cap Check | M34: In-Place 4/26 | N34: Tier
B35: 1BR/1BA - HAP | C35: 49 | D35: 656 | E35: 942 | F35: 0 | G35: =E35*$M$33 -> 942 | H35: =G35*(1+PostRehabUplift) -> 1036.2 | I35: 1176 | J35: 1470 | K35: 1063 | L35: =IF(H35<=MIN(I35,J35),"PASS","FAIL") -> PASS | M35: 875 | N35: HAP
B36: 2BR/1BA - HAP | C36: 28 | D36: 806 | E36: 1011 | F36: 0 | G36: =E36*$M$33 -> 1011 | H36: =G36*(1+PostRehabUplift) -> 1112.1 | I36: 1321 | J36: 1650 | K36: 1276 | L36: =IF(H36<=MIN(I36,J36),"PASS","FAIL") -> PASS | M36: 940 | N36: HAP
B37: 2BR/1.5BA TH - HAP | C37: 25 | D37: 903 | E37: 1049 | F37: 0 | G37: =E37*$M$33 -> 1049 | H37: =G37*(1+PostRehabUplift) -> 1153.9 | I37: 1321 | J37: 1650 | K37: 1276 | L37: =IF(H37<=MIN(I37,J37),"PASS","FAIL") -> PASS | M37: 975 | N37: HAP
B38: 3BR/1.5BA - HAP | C38: 21 | D38: 903 | E38: 1184 | F38: 0 | G38: =E38*$M$33 -> 1184 | H38: =G38*(1+PostRehabUplift) -> 1302.4 | I38: 1499 | J38: 2070 | K38: 1474 | L38: =IF(H38<=MIN(I38,J38),"PASS","FAIL") -> PASS | M38: 1100 | N38: HAP
B39: 1BR/1BA - 50% AMI | C39: 1 | D39: 795 | E39: 769 | F39: 0 | G39: =E39*$M$33 -> 769 | H39: =G39*(1+PostRehabUplift) -> 845.9 | I39: 1176 | J39: 1470 | K39: 886 | L39: =IF(H39<=K39,"PASS","FAIL") -> PASS | M39: 769 | N39: LIHTC
B40: 1BR/1BA - 60% AMI | C40: 1 | D40: 795 | E40: 649 | F40: 0 | G40: =E40*$M$33 -> 649 | H40: =G40*(1+PostRehabUplift) -> 713.9 | I40: 1176 | J40: 1470 | K40: 1063 | L40: =IF(H40<=K40,"PASS","FAIL") -> PASS | M40: 649 | N40: LIHTC
B41: 2BR/1BA - 50% AMI | C41: 2 | D41: 806 | E41: 630 | F41: 0 | G41: =E41*$M$33 -> 630 | H41: =G41*(1+PostRehabUplift) -> 693 | I41: 1321 | J41: 1650 | K41: 1063 | L41: =IF(H41<=K41,"PASS","FAIL") -> PASS | M41: 630 | N41: LIHTC
B42: 2BR/1BA - 60% AMI | C42: 18 | D42: 806 | E42: 647.88 | F42: 0 | G42: =E42*$M$33 -> 647.88 | H42: =G42*(1+PostRehabUplift) -> 712.668 | I42: 1321 | J42: 1650 | K42: 1276 | L42: =IF(H42<=K42,"PASS","FAIL") -> PASS | M42: 647.88 | N42: LIHTC
B43: 2BR/1.5BA TH - 50% AMI | C43: 3 | D43: 903 | E43: 650 | F43: 0 | G43: =E43*$M$33 -> 650 | H43: =G43*(1+PostRehabUplift) -> 715 | I43: 1321 | J43: 1650 | K43: 1063 | L43: =IF(H43<=K43,"PASS","FAIL") -> PASS | M43: 650 | N43: LIHTC
B44: 2BR/1.5BA TH - 60% AMI | C44: 20 | D44: 903 | E44: 668.5 | F44: 0 | G44: =E44*$M$33 -> 668.5 | H44: =G44*(1+PostRehabUplift) -> 735.35 | I44: 1321 | J44: 1650 | K44: 1276 | L44: =IF(H44<=K44,"PASS","FAIL") -> PASS | M44: 668.5 | N44: LIHTC
...

Sheet Rev+Expenses
A1: REVENUE + EXPENSES — STABILIZED YEAR-1 SNAPSHOT (each property's close-year $)
B2: HAP contract-rent revenue engine per spec Sec. 5.3 — not market rents. Each column is stated in that property's resyndication-close-year dollars (rents OCAF-trended on Unit Mix+Rents; expenses trended below). Portfolio column mixes vintages — caveat.
C3: Clear Horizons | D3: New Zion | E3: Live Oak Manor | F3: Spanish Arms | G3: Portfolio (mixed-vintage)
B5: HAP rental income | C5: =SUMPRODUCT((CH_MixTier="HAP")*CH_MixCount*CH_MixPR)*12 -> 1166597.5 | D5: =SUMPRODUCT((NZ_MixTier="HAP")*NZ_MixCount*NZ_MixPR)*12 -> 1427889.7 | E5: =SUMPRODUCT((LOM_MixTier="HAP")*LOM_MixCount*LOM_MixPR)*12 -> 1791762.3 | F5: =SUMPRODUCT((SA_MixTier="HAP")*SA_MixCount*SA_MixPR)*12 -> 1657326 | G5: =SUM(C5:F5) -> 6043575.6
B6: Non-HAP LIHTC income (SA) | C6: =SUMPRODUCT((CH_MixTier="LIHTC")*CH_MixCount*CH_MixPR)*12 -> 0 | D6: =SUMPRODUCT((NZ_MixTier="LIHTC")*NZ_MixCount*NZ_MixPR)*12 -> 0 | E6: =SUMPRODUCT((LOM_MixTier="LIHTC")*LOM_MixCount*LOM_MixPR)*12 -> 0 | F6: =SUMPRODUCT((SA_MixTier="LIHTC")*SA_MixCount*SA_MixPR)*12 -> 707913.89 | G6: =SUM(C6:F6) -> 707913.89
B7: Market income (SA) | C7: =SUMPRODUCT((CH_MixTier="MKT")*CH_MixCount*CH_MixPR)*12 -> 0 | D7: =SUMPRODUCT((NZ_MixTier="MKT")*NZ_MixCount*NZ_MixPR)*12 -> 0 | E7: =SUMPRODUCT((LOM_MixTier="MKT")*LOM_MixCount*LOM_MixPR)*12 -> 0 | F7: =SUMPRODUCT((SA_MixTier="MKT")*SA_MixCount*SA_MixPR)*12 -> 17740.8 | G7: =SUM(C7:F7) -> 17740.8
B8: Gross potential rent | C8: =SUM(C5:C7) -> 1166597.5 | D8: =SUM(D5:D7) -> 1427889.7 | E8: =SUM(E5:E7) -> 1791762.3 | F8: =SUM(F5:F7) -> 2382980.7 | G8: =SUM(C8:F8) -> 6769230.2
B9: Other income | C9: 13095 | D9: 14577 | E9: 12732 | F9: 34962 | G9: =SUM(C9:F9) -> 75366
B11: HAP vacancy % | C11: 0.0357 | D11: 0.02 | E11: 0.0756 | F11: 0.0931
B12: Non-HAP vacancy % | C12: n/a | D12: n/a | E12: n/a | F12: 0.0931
B13: Vacancy adjustment | C13: =-(C5*C11+0) -> -41647.531 | D13: =-(D5*D11+0) -> -28557.795 | E13: =-(E5*E11+0) -> -135457.23 | F13: =-(F5*F11+(F6+F7)*F12) -> -221855.5 | G13: =SUM(C13:F13) -> -427518.06
B15: Effective gross income (EGI) | C15: =SUM(C8:C9)+C13 -> 1138045 | D15: =SUM(D8:D9)+D13 -> 1413908.9 | E15: =SUM(E8:E9)+E13 -> 1669037.1 | F15: =SUM(F8:F9)+F13 -> 2196087.2 | G15: =SUM(C15:F15) -> 6417078.2
B17: Operating Expenses (trended to close year; insurance on its own trend)
B18: Management fee | C18: =MgmtFeePct*C15 -> 45521.8 | D18: =MgmtFeePct*D15 -> 56556.358 | E18: =MgmtFeePct*E15 -> 66761.483 | F18: =MgmtFeePct*F15 -> 87843.487 | G18: =SUM(C18:F18) -> 256683.13
B19: Administrative (ex-mgmt fee) | C19: =(CH_OpexAdmin-CH_MgmtFeeCell)*(1+ExpGrowth)^CH_InflYears -> 163492.12 | D19: =(NZ_OpexAdmin-NZ_MgmtFeeCell)*(1+ExpGrowth)^NZ_InflYears -> 184096.09 | E19: =(LOM_OpexAdmin-LOM_MgmtFeeCell)*(1+ExpGrowth)^LOM_InflYears -> 175065.79 | F19: =(SA_OpexAdmin-SA_MgmtFeeCell)*(1+ExpGrowth)^SA_InflYears -> 247995 | G19: =SUM(C19:F19) -> 770649
B20: Utilities | C20: =CH_OpexUtil*(1+ExpGrowth)^CH_InflYears -> 137600.85 | D20: =NZ_OpexUtil*(1+ExpGrowth)^NZ_InflYears -> 72790.916 | E20: =LOM_OpexUtil*(1+ExpGrowth)^LOM_InflYears -> 134399.96 | F20: =SA_OpexUtil*(1+ExpGrowth)^SA_InflYears -> 346747 | G20: =SUM(C20:F20) -> 691538.73
B21: Operating & maintenance | C21: =CH_OpexOM*(1+ExpGrowth)^CH_InflYears -> 349669.46 | D21: =NZ_OpexOM*(1+ExpGrowth)^NZ_InflYears -> 400028.78 | E21: =LOM_OpexOM*(1+ExpGrowth)^LOM_InflYears -> 409497.26 | F21: =SA_OpexOM*(1+ExpGrowth)^SA_InflYears -> 415840 | G21: =SUM(C21:F21) -> 1575035.5
B22: Taxes (RE & PP) + other T&I (ex-insurance) | C22: =(CH_OpexTI-CH_InsExp)*(1+ExpGrowth)^CH_InflYears -> 74675.69 | D22: =(NZ_OpexTI-NZ_InsExp)*(1+ExpGrowth)^NZ_InflYears -> 84935.484 | E22: =(LOM_OpexTI-LOM_InsExp)*(1+ExpGrowth)^LOM_InflYears -> 64905.798 | F22: =(SA_OpexTI-SA_InsExp)*(1+ExpGrowth)^SA_InflYears -> 100168 | G22: =SUM(C22:F22) -> 324684.97
B23: Property & liability insurance | C23: =CH_InsExp*(1+InsGrowth)^CH_InflYears -> 98737.474 | D23: =NZ_InsExp*(1+InsGrowth)^NZ_InflYears -> 105204.83 | E23: =LOM_InsExp*(1+InsGrowth)^LOM_InflYears -> 205310.91 | F23: =SA_InsExp*(1+InsGrowth)^SA_InflYears -> 272022 | G23: =SUM(C23:F23) -> 681275.21
B24: Total operating expenses | C24: =SUM(C18:C23) -> 869697.39 | D24: =SUM(D18:D23) -> 903612.45 | E24: =SUM(E18:E23) -> 1055941.2 | F24: =SUM(F18:F23) -> 1470615.5 | G24: =SUM(C24:F24) -> 4299866.5
B26: NET OPERATING INCOME | C26: =C15-C24 -> 268347.6 | D26: =D15-D24 -> 510296.49 | E26: =E15-E24 -> 613095.87 | F26: =F15-F24 -> 725471.7 | G26: =SUM(C26:F26) -> 2117211.7
B28: Replacement reserves (below NOI) | C28: =CH_Reserves*(1+ExpGrowth)^CH_InflYears -> 31190.46 | D28: =NZ_Reserves*(1+ExpGrowth)^NZ_InflYears -> 38245.445 | E28: =LOM_Reserves*(1+ExpGrowth)^LOM_InflYears -> 45512.08 | F28: =SA_Reserves*(1+ExpGrowth)^SA_InflYears -> 71400 | G28: =SUM(C28:F28) -> 186347.98
B29: Cash flow before debt service | C29: =C26-C28 -> 237157.14 | D29: =D26-D28 -> 472051.04 | E29: =E26-E28 -> 567583.79 | F29: =F26-F28 -> 654071.7 | G29: =SUM(C29:F29) -> 1930863.7
B31: Ratios
B32: Opex % of EGI | C32: =C24/C15 -> 0.76420299 | D32: =D24/D15 -> 0.63908815 | E32: =E24/E15 -> 0.63266492 | F32: =F24/F15 -> 0.6696526
B33: NOI % of EGI | C33: =C26/C15 -> 0.23579701 | D33: =D26/D15 -> 0.36091185 | E33: =E26/E15 -> 0.36733508 | F33: =F26/F15 -> 0.3303474
B34: Opex PUPA (close-year $) | C34: =C24/CH_Units -> 10353.54 | D34: =D24/NZ_Units -> 9036.1245 | E34: =E24/LOM_Units -> 8873.4555 | F34: =F24/SA_Units -> 7208.8994

Sheet Expense Detail
A1: EXPENSE DETAIL — AUDIT / BUDGET / OM / MODEL COMPARISON
B2: Per spec Sec. 5.4: every line compares 2025 audit | 2026 budget | OM 'market expenses' | model assumption (blue). Insurance carries its own growth rate (InsGrowth) and is never blended into the general trend. Model assumptions follow the OM market-expense basis EXCEPT insurance and taxes, which use DD-documented values (broker figures unsupported — see variance notes on OM Actuals).
B4: CLEAR HORIZONS | C4: 2025 Audit | D4: 2026 Budget | E4: OM Market | F4: Model (UW) | G4: PUPA
B5: ADMINISTRATIVE
B6: Advertising & marketing | C6: 175 | D6: 0 | E6: 865.5 | F6: 866 | G6: =F6/CH_Units -> 10.309524
B7: Other renting expense | C7: 0 | D7: 6226 | E7: 1500 | F7: 1500 | G7: =F7/CH_Units -> 17.857143
B8: Office salaries | C8: 97415 | D8: 97491 | E8: 22963.2 | F8: 22963 | G8: =F8/CH_Units -> 273.36905
B9: Office expenses | C9: 22147 | D9: 19547 | E9: 19547 | F9: 19547 | G9: =F9/CH_Units -> 232.70238
B10: Management fee | C10: 36538 | D10: 35892 | E10: 40082.712 | F10: ='Rev+Expenses'!C18 -> 45521.8 | G10: =F10/CH_Units -> 541.92619
B11: Manager salaries | C11: 0 | D11: 0 | E11: 60500 | F11: 60500 | G11: =F11/CH_Units -> 720.2381
B12: Legal | C12: 6288 | D12: 9368 | E12: 5000 | F12: 5000 | G12: =F12/CH_Units -> 59.52381
B13: Audit | C13: 9900 | D13: 10188 | E13: 7500 | F13: 7500 | G13: =F13/CH_Units -> 89.285714
B14: Bad debts | C14: 32446 | D14: 33552 | E14: 31230.72 | F14: 31231 | G14: =F14/CH_Units -> 371.79762
B15: Misc administrative | C15: 27494 | D15: 9031 | E15: 5000 | F15: 5000 | G15: =F15/CH_Units -> 59.52381
B16: Total administrative | C16: =SUM(C6:C15) -> 232403 | D16: =SUM(D6:D15) -> 221295 | E16: =SUM(E6:E15) -> 194189.13 | F16: =SUM(F6:F15) -> 199628.8 | G16: =F16/CH_Units -> 2376.5333
B17: UTILITIES
B18: Electricity | C18: 19230 | D18: 20100 | E18: 20100 | F18: 20100 | G18: =F18/CH_Units -> 239.28571
B19: Gas | C19: 0 | D19: 0 | E19: 0 | F19: 0 | G19: =F19/CH_Units -> 0
B20: Water | C20: 100722 | D20: 109602 | E20: 109602 | F20: 109602 | G20: =F20/CH_Units -> 1304.7857
B21: Sewer | C21: 0 | D21: 0 | E21: 0 | F21: 0 | G21: =F21/CH_Units -> 0
B22: Total utilities | C22: =SUM(C18:C21) -> 119952 | D22: =SUM(D18:D21) -> 129702 | E22: =SUM(E18:E21) -> 129702 | F22: =SUM(F18:F21) -> 129702 | G22: =F22/CH_Units -> 1544.0714
B23: OPERATING & MAINTENANCE
B24: Maintenance payroll | C24: 139997 | D24: 102132 | E24: 96636.8 | F24: 96637 | G24: =F24/CH_Units -> 1150.4405
B25: Supplies | C25: 79805 | D25: 49224 | E25: 42000 | F25: 42000 | G25: =F25/CH_Units -> 500
B26: Contracts | C26: 176549 | D26: 116549 | E26: 42000 | F26: 42000 | G26: =F26/CH_Units -> 500
B27: Garbage & trash | C27: 28949 | D27: 21372 | E27: 21372 | F27: 21372 | G27: =F27/CH_Units -> 254.42857
B28: Security | C28: 111722 | D28: 120088 | E28: 120088 | F28: 120088 | G28: =F28/CH_Units -> 1429.619
B29: Heating/cooling repairs | C29: 1825 | D29: 18851 | E29: 7500 | F29: 7500 | G29: =F29/CH_Units -> 89.285714
B30: Misc operating & maintenance | C30: 0 | D30: 330 | E30: 0 | F30: 0 | G30: =F30/CH_Units -> 0
B31: Total operating & maintenance | C31: =SUM(C24:C30) -> 538847 | D31: =SUM(D24:D30) -> 428546 | E31: =SUM(E24:E30) -> 329596.8 | F31: =SUM(F24:F30) -> 329597 | G31: =F31/CH_Units -> 3923.7738
B32: TAXES & INSURANCE
B33: Real estate & personal property taxes | C33: 33198 | D33: 30384 | E33: 33198.37 | F33: 33198 | G33: =F33/CH_Units -> 395.21429
B34: Payroll taxes | C34: 18421 | D34: 16333 | E34: 13777.65 | F34: 13778 | G34: =F34/CH_Units -> 164.02381
B35: Property & liability insurance | C35: 92566 | D35: 87876 | E35: 79504 | F35: 87876 | G35: =F35/CH_Units -> 1046.1429
B36: Workers compensation | C36: 677 | D36: 3368 | E36: 5403 | F36: 5403 | G36: =F36/CH_Units -> 64.321429
B37: Health insurance & benefits | C37: 13035 | D37: 16160 | E37: 18010 | F37: 18010 | G37: =F37/CH_Units -> 214.40476
B38: Misc taxes/licenses/insurance | C38: 760 | D38: 0 | E38: 0 | F38: 0 | G38: =F38/CH_Units -> 0
B39: Total taxes & insurance | C39: =SUM(C33:C38) -> 158657 | D39: =SUM(D33:D38) -> 154121 | E39: =SUM(E33:E38) -> 149893.02 | F39: =SUM(F33:F38) -> 158265 | G39: =F39/CH_Units -> 1884.1071
B40: TOTAL OPERATING EXPENSES (before reserves) | C40: =C16+C22+C31+C39 -> 1049859 | D40: =D16+D22+D31+D39 -> 933664 | E40: =E16+E22+E31+E39 -> 803380.95 | F40: =F16+F22+F31+F39 -> 817192.8 | G40: =F40/CH_Units -> 9728.4857
B41: Replacement reserves (below NOI) | C41: 18937 | D41: 18937 | E41: 25200 | F41: =MAX(ReserveFloorFamily*CH_Units,25200) -> 29400 | G41: =F41/CH_Units -> 350
...

Sheet Rehab Scope
A1: REHAB SCOPE — $/UNIT BUILD-UP & TENANT RELOCATION
B2: No CNA or rehab budget exists (spec Gap #2) — every hard-cost input on this sheet is a $40,000/unit PLACEHOLDER allocation per user decision 8/6/26. Replace with CNA data.
B3: Hard Costs ($/unit) | C3: Clear Horizons | D3: New Zion | E3: Live Oak Manor | F3: Spanish Arms | G3: Portfolio
B4: Unit interiors | C4: 20000 | D4: 20000 | E4: 20000 | F4: 20000
B5: Roofs | C5: 6000 | D5: 6000 | E5: 6000 | F5: 6000
B6: HVAC | C6: 6000 | D6: 6000 | E6: 6000 | F6: 6000
B7: Plumbing | C7: 4000 | D7: 4000 | E7: 4000 | F7: 4000
B8: Site work | C8: 4000 | D8: 4000 | E8: 4000 | F8: 4000
B9: Base hard cost / unit | C9: =SUM(C4:C8) -> 40000 | D9: =SUM(D4:D8) -> 40000 | E9: =SUM(E4:E8) -> 40000 | F9: =SUM(F4:F8) -> 40000
B10: Check vs Dashboard RehabPerUnit | C10: =IF(C9=RehabPerUnit,"OK","MISMATCH") -> OK | D10: =IF(D9=RehabPerUnit,"OK","MISMATCH") -> OK | E10: =IF(E9=RehabPerUnit,"OK","MISMATCH") -> OK | F10: =IF(F9=RehabPerUnit,"OK","MISMATCH") -> OK
B11: Construction contingency | C11: =C9*ContingencyPct -> 4000 | D11: =D9*ContingencyPct -> 4000 | E11: =E9*ContingencyPct -> 4000 | F11: =F9*ContingencyPct -> 4000
B12: GC fees (gen req + overhead + profit) | C12: =C9*(GenReqPct+BuilderOHPct+BuilderProfitPct) -> 5600 | D12: =D9*(GenReqPct+BuilderOHPct+BuilderProfitPct) -> 5600 | E12: =E9*(GenReqPct+BuilderOHPct+BuilderProfitPct) -> 5600 | F12: =F9*(GenReqPct+BuilderOHPct+BuilderProfitPct) -> 5600
B13: Total rehab cost / unit (2026 $) | C13: =C9+C11+C12 -> 49600 | D13: =D9+D11+D12 -> 49600 | E13: =E9+E11+E12 -> 49600 | F13: =F9+F11+F12 -> 49600
B14: Total rehab cost (2026 $) | C14: =C13*CH_Units -> 4166400 | D14: =D13*NZ_Units -> 4960000 | E14: =E13*LOM_Units -> 5902400 | F14: =F13*SA_Units -> 10118400 | G14: =SUM(C14:F14) -> 25147200
B15: Hard cost / SF | C15: =C14/CH_NRSF -> 56.443048 | D15: =D14/NZ_NRSF -> 69.651182 | E15: =E14/LOM_NRSF -> 57.807725 | F15: =F14/SA_NRSF -> 52.718671
B17: MINIMUM-REHAB TESTS (feed Scorecard)
B18: Base hard cost/unit vs IRC Sec.42(e)(3)(A)(ii) min | C18: =IF(C9>=MinRehabIRC,"PASS","FAIL") -> PASS | D18: =IF(D9>=MinRehabIRC,"PASS","FAIL") -> PASS | E18: =IF(E9>=MinRehabIRC,"PASS","FAIL") -> PASS | F18: =IF(F9>=MinRehabIRC,"PASS","FAIL") -> PASS
B19: Base hard cost/unit vs LA QAP rehab minimum | C19: =IF(MinRehabQAP="","PENDING",IF(C9>=MinRehabQAP,"PASS","FAIL")) -> PENDING | D19: =IF(MinRehabQAP="","PENDING",IF(D9>=MinRehabQAP,"PASS","FAIL")) -> PENDING | E19: =IF(MinRehabQAP="","PENDING",IF(E9>=MinRehabQAP,"PASS","FAIL")) -> PENDING | F19: =IF(MinRehabQAP="","PENDING",IF(F9>=MinRehabQAP,"PASS","FAIL")) -> PENDING
B21: TENANT RELOCATION (properties are 91-98% occupied — spec Sec. 5.5)
B22: Relocation Inputs | C22: Clear Horizons | D22: New Zion | E22: Live Oak Manor | F22: Spanish Arms | G22: Portfolio
B23: Relocation method | C23: In-place phased | D23: In-place phased | E23: In-place phased | F23: In-place phased
B24: Units relocated per month | C24: =ROUNDUP(CH_Units/CH_RehabMonths,0) -> 7 | D24: =ROUNDUP(NZ_Units/NZ_RehabMonths,0) -> 9 | E24: =ROUNDUP(LOM_Units/LOM_RehabMonths,0) -> 8 | F24: =ROUNDUP(SA_Units/SA_RehabMonths,0) -> 12
B25: Downtime per unit (months) | C25: 0.5 | D25: 0.5 | E25: 0.5 | F25: 0.5
B26: Temporary housing / hotel ($/unit) | C26: 800 | D26: 800 | E26: 800 | F26: 800
B27: Moving costs — out ($/unit) | C27: 400 | D27: 400 | E27: 400 | F27: 400
B28: Moving costs — back ($/unit) | C28: 400 | D28: 400 | E28: 400 | F28: 400
B29: Meals / incidentals per-diem ($/unit) | C29: 300 | D29: 300 | E29: 300 | F29: 300
B30: Storage ($/unit) | C30: 200 | D30: 200 | E30: 200 | F30: 200
B31: Staff coordination ($/unit) | C31: 400 | D31: 400 | E31: 400 | F31: 400
B32: Relocation $/unit | C32: =SUM(C26:C31) -> 2500 | D32: =SUM(D26:D31) -> 2500 | E32: =SUM(E26:E31) -> 2500 | F32: =SUM(F26:F31) -> 2500
B33: Check vs Dashboard RelocPerUnit | C33: =IF(C32=RelocPerUnit,"OK","MISMATCH") -> OK | D33: =IF(D32=RelocPerUnit,"OK","MISMATCH") -> OK | E33: =IF(E32=RelocPerUnit,"OK","MISMATCH") -> OK | F33: =IF(F32=RelocPerUnit,"OK","MISMATCH") -> OK
B34: Total tenant relocation (2026 $) | C34: =C32*CH_Units -> 210000 | D34: =D32*NZ_Units -> 250000 | E34: =E32*LOM_Units -> 297500 | F34: =F32*SA_Units -> 510000 | G34: =SUM(C34:F34) -> 1267500
B35: URA applicability: PENDING — if HOME/CDBG or other federal funds enter the stack, Uniform Relocation Act notices/payments apply and costs rise materially. New Zion's existing stack includes a HOME loan (DD folder). Scorecard carries a PENDING flag.
B37: REHAB-PERIOD REVENUE DISRUPTION
B38: Avg units offline during rehab | C38: =C24*C25 -> 3.5 | D38: =D24*D25 -> 4.5 | E38: =E24*E25 -> 4 | F38: =F24*F25 -> 6
B39: Offline vacancy adj (% of GPR, rehab months) | C39: =C38/CH_Units -> 0.041666667 | D39: =D38/NZ_Units -> 0.045 | E39: =E38/LOM_Units -> 0.033613445 | F39: =F38/SA_Units -> 0.029411765
B41: REHAB BURN CURVE — % of rehab cost drawn per month from resyndication close (M1-M18; occupied-rehab curve, spec Sec. 5.12)
B42: Month | C42: Clear Horizons | D42: New Zion | E42: Live Oak Manor | F42: Spanish Arms
B43: 1 | C43: 0.017 | D43: 0.017 | E43: 0.0109 | F43: 0.0076
B44: 2 | C44: 0.05 | D44: 0.05 | E44: 0.0323 | F44: 0.0226
...

Sheet Sources & Uses
A1: SOURCES AND USES — RESYNDICATION CLOSINGS (each column in its vintage-year dollars)
C3: Clear Horizons | D3: New Zion | E3: Live Oak Manor | F3: Spanish Arms | G3: Portfolio
B4: Resyndication close | C4: =CH_ResynDate -> 46753 | D4: =NZ_ResynDate -> 47119 | E4: =LOM_ResynDate -> 47119 | F4: =SA_ResynDate -> 46357 | G4: mixed vintages
B5: Dollars stated in each column are that close-year's dollars — rehab and fee lines cost-inflated at CostInflation (Dashboard). The Portfolio column sums MIXED-VINTAGE dollars (2026 + 2028 + 2029) — treat as indicative only (spec Sec. 2).
B7: SOURCES
B8: Perm / tax-exempt bond proceeds | C8: =CH_SelProceeds -> 3410352.4 | D8: =NZ_SelProceeds -> 6485211.1 | E8: =LOM_SelProceeds -> 7791658.8 | F8: =SA_SelProceeds -> 9219810.9 | G8: =SUM(C8:F8) -> 26907033
B9: 4% LIHTC equity | C9: =CH_Equity -> 2241868.1 | D9: =NZ_Equity -> 2775646.2 | E9: =LOM_Equity -> 4110859 | F9: =SA_Equity -> 5117769.8 | G9: =SUM(C9:F9) -> 14246143
B10: Deferred developer fee | C10: =MIN(C24,MAX(0,C26-(C8+C9+C11+C12))) -> 816531.21 | D10: =MIN(D24,MAX(0,D26-(D8+D9+D11+D12))) -> 1010943.4 | E10: =MIN(E24,MAX(0,E26-(E8+E9+E11+E12))) -> 1571626.8 | F10: =MIN(F24,MAX(0,F26-(F8+F9+F11+F12))) -> 1799327.9 | G10: =SUM(C10:F10) -> 5198429.2
B11: Bridge-period cash contributed | C11: =MAX(0,CH_BridgeCF) -> 0 | D11: =MAX(0,NZ_BridgeCF) -> 186952.92 | E11: =MAX(0,LOM_BridgeCF) -> 152373.65 | F11: =MAX(0,SA_BridgeCF) -> 0 | G11: =SUM(C11:F11) -> 339326.56
B12: Soft funds REQUIRED (unfunded gap plug) | C12: =MAX(0,C26-(C8+C9+C11+C24)) -> 461898.42 | D12: =MAX(0,D26-(D8+D9+D11+D24)) -> 148039.11 | E12: =MAX(0,E26-(E8+E9+E11+E24)) -> 0 | F12: =MAX(0,F26-(F8+F9+F11+F24)) -> 0 | G12: =SUM(C12:F12) -> 609937.53
B13: TOTAL SOURCES | C13: =SUM(C8:C12) -> 6930650.1 | D13: =SUM(D8:D12) -> 10606793 | E13: =SUM(E8:E12) -> 13626518 | F13: =SUM(F8:F12) -> 16136909 | G13: =SUM(C13:F13) -> 47300870
B15: USES
B16: Acquisition price | C16: =CH_AcqPrice -> 0 | D16: =NZ_AcqPrice -> 0 | E16: =LOM_AcqPrice -> 3000000 | F16: =SA_AcqPrice -> 500000 | G16: =SUM(C16:F16) -> 3500000
B17: NZ HOME loan payoff (principal + accrued) | C17: 0 | D17: =NZ_HOMEPayoff -> 2027484.6 | E17: 0 | F17: 0 | G17: =SUM(C17:F17) -> 2027484.6
B18: Rehab (hard + relocation + soft, vintage $) | C18: =CH_RehabBasis -> 5443541.4 | D18: =NZ_RehabBasis -> 6739622.7 | E18: =LOM_RehabBasis -> 8020151 | F18: =SA_RehabBasis -> 12222660 | G18: =SUM(C18:F18) -> 32425975
B19: Financing fees (perm origination/placement/legal) | C19: =CH_FinFees -> 51155.286 | D19: =NZ_FinFees -> 97278.167 | E19: =LOM_FinFees -> 116874.88 | F19: =SA_FinFees -> 138297.16 | G19: =SUM(C19:F19) -> 403605.5
B20: Bond cost of issuance | C20: 0.02 | D20: 0.02 | E20: 0.02 | F20: 0.02
B21: Bond COI $ | C21: =C20*C8 -> 68207.048 | D21: =D20*D8 -> 129704.22 | E21: =E20*E8 -> 155833.18 | F21: =F20*F8 -> 184396.22 | G21: =SUM(C21:F21) -> 538140.66
B22: Construction-period interest (net) | C22: =CH_ConstrInt -> 116366.47 | D22: =NZ_ConstrInt -> 149953.45 | E22: =LOM_ConstrInt -> 220165.97 | F22: =SA_ConstrInt -> 459098.41 | G22: =SUM(C22:F22) -> 945584.31
B23: Operating reserve | C23: =OpReserveFrac*CH_OpexStab -> 434848.69 | D23: =OpReserveFrac*NZ_OpexStab -> 451806.23 | E23: =OpReserveFrac*LOM_OpexStab -> 527970.6 | F23: =OpReserveFrac*SA_OpexStab -> 735307.74 | G23: =SUM(C23:F23) -> 2149933.3
B24: Developer fee | C24: =C25*(CH_AcqBasis+CH_RehabBasis) -> 816531.21 | D24: =D25*(NZ_AcqBasis+NZ_RehabBasis) -> 1010943.4 | E24: =E25*(LOM_AcqBasis+LOM_RehabBasis) -> 1585522.6 | F24: =F25*(SA_AcqBasis+SA_RehabBasis) -> 1897149 | G24: =SUM(C24:F24) -> 5310146.2
B25: Developer fee % | C25: 0.15 | D25: 0.15 | E25: 0.15 | F25: 0.15
B26: TOTAL USES | C26: =SUM(C16:C18)+C19+SUM(C21:C24) -> 6930650.1 | D26: =SUM(D16:D18)+D19+SUM(D21:D24) -> 10606793 | E26: =SUM(E16:E18)+E19+SUM(E21:E24) -> 13626518 | F26: =SUM(F16:F18)+F19+SUM(F21:F24) -> 16136909 | G26: =SUM(C26:F26) -> 47300870
B28: BALANCE & MEMO
B29: Sources - Uses (surplus / (shortfall)) | C29: =C13-C26 -> 0 | D29: =D13-D26 -> 0 | E29: =E13-E26 -> 0 | F29: =F13-F26 -> 0 | G29: =SUM(C29:F29) -> 0
B30: Balanced? | C30: =IF(ABS(C29)<=SUBalanceTol,"OK",IF(C29<0,"SHORTFALL","SURPLUS")) -> OK | D30: =IF(ABS(D29)<=SUBalanceTol,"OK",IF(D29<0,"SHORTFALL","SURPLUS")) -> OK | E30: =IF(ABS(E29)<=SUBalanceTol,"OK",IF(E29<0,"SHORTFALL","SURPLUS")) -> OK | F30: =IF(ABS(F29)<=SUBalanceTol,"OK",IF(F29<0,"SHORTFALL","SURPLUS")) -> OK
B31: Deferred fee % of developer fee | C31: =IF(C24=0,0,C10/C24) -> 1 | D31: =IF(D24=0,0,D10/D24) -> 1 | E31: =IF(E24=0,0,E10/E24) -> 0.99123578 | F31: =IF(F24=0,0,F10/F24) -> 0.94843781
B32: TDC / unit (vintage $) | C32: =C26/CH_Units -> 82507.739 | D32: =D26/NZ_Units -> 106067.93 | E32: =E26/LOM_Units -> 114508.56 | F32: =F26/SA_Units -> 79102.493
B33: TDC limit / unit (HUD/LHC) | C33: =CH_TDCLimitPU -> 296008.48 | D33: =NZ_TDCLimitPU -> 271516.84 | E33: =LOM_TDCLimitPU -> 367877.08 | F33: =SA_TDCLimitPU -> 269505.86

Sheet S&U Timing
A1: S&U TIMING — MONTHLY DRAWS FROM EACH RESYNDICATION CLOSE (M1-M18)
B2: Sizing engine (spec Sec. 5.12): equity tranches placed by pay-in month (Tax Credit Calc), uses drawn per the Rehab Scope burn curve, perm/bond draws plug the need, construction interest capitalizes on the drawn balance, and max outstanding feeds Financing. Deferred fee is excluded from cash uses.
B4: CLEAR HORIZONS — close: | D4: =CH_ResynDate -> 46753
B5: Month | C5: 1 | D5: 2 | E5: 3 | F5: 4 | G5: 5 | H5: 6 | I5: 7 | J5: 8 | K5: 9 | L5: 10 | M5: 11 | N5: 12 | O5: 13 | P5: 14 | Q5: 15 | R5: 16 | S5: 17 | T5: 18 | U5: TOTAL
B6: Calendar month | C6: =EDATE(CH_ResynDate,0) -> 46753 | D6: =EDATE(CH_ResynDate,1) -> 46784 | E6: =EDATE(CH_ResynDate,2) -> 46813 | F6: =EDATE(CH_ResynDate,3) -> 46844 | G6: =EDATE(CH_ResynDate,4) -> 46874 | H6: =EDATE(CH_ResynDate,5) -> 46905 | I6: =EDATE(CH_ResynDate,6) -> 46935 | J6: =EDATE(CH_ResynDate,7) -> 46966 | K6: =EDATE(CH_ResynDate,8) -> 46997 | L6: =EDATE(CH_ResynDate,9) -> 47027 | M6: =EDATE(CH_ResynDate,10) -> 47058 | N6: =EDATE(CH_ResynDate,11) -> 47088 | O6: =EDATE(CH_ResynDate,12) -> 47119 | P6: =EDATE(CH_ResynDate,13) -> 47150 | Q6: =EDATE(CH_ResynDate,14) -> 47178 | R6: =EDATE(CH_ResynDate,15) -> 47209 | S6: =EDATE(CH_ResynDate,16) -> 47239 | T6: =EDATE(CH_ResynDate,17) -> 47270
B7: Acquisition price (M1) | C7: =IF(C5=1,CH_AcqPrice,0) -> 0 | D7: =IF(D5=1,CH_AcqPrice,0) -> 0 | E7: =IF(E5=1,CH_AcqPrice,0) -> 0 | F7: =IF(F5=1,CH_AcqPrice,0) -> 0 | G7: =IF(G5=1,CH_AcqPrice,0) -> 0 | H7: =IF(H5=1,CH_AcqPrice,0) -> 0 | I7: =IF(I5=1,CH_AcqPrice,0) -> 0 | J7: =IF(J5=1,CH_AcqPrice,0) -> 0 | ... T7: =IF(T5=1,CH_AcqPrice,0) -> 0 | U7: =SUM(C7:T7) -> 0
B8: Other close payments (M1) | C8: 0 | D8: 0 | E8: 0 | F8: 0 | G8: 0 | H8: 0 | I8: 0 | J8: 0 | K8: 0 | L8: 0 | M8: 0 | N8: 0 | O8: 0 | P8: 0 | Q8: 0 | R8: 0 | S8: 0 | T8: 0 | U8: =SUM(C8:T8) -> 0
B9: Rehab draw (burn curve) | C9: =CH_RehabBasis*INDEX(CH_BurnCurve,1) -> 92540.203 | D9: =CH_RehabBasis*INDEX(CH_BurnCurve,2) -> 272177.07 | E9: =CH_RehabBasis*INDEX(CH_BurnCurve,3) -> 432761.54 | F9: =CH_RehabBasis*INDEX(CH_BurnCurve,4) -> 563950.89 | G9: =CH_RehabBasis*INDEX(CH_BurnCurve,5) -> 656491.09 | H9: =CH_RehabBasis*INDEX(CH_BurnCurve,6) -> 704394.25 | I9: =CH_RehabBasis*INDEX(CH_BurnCurve,7) -> 704394.25 | J9: =CH_RehabBasis*INDEX(CH_BurnCurve,8) -> 656491.09 | K9: =CH_RehabBasis*INDEX(CH_BurnCurve,9) -> 563950.89 | L9: =CH_RehabBasis*INDEX(CH_BurnCurve,10) -> 432761.54 | M9: =CH_RehabBasis*INDEX(CH_BurnCurve,11) -> 272177.07 | N9: =CH_RehabBasis*INDEX(CH_BurnCurve,12) -> 91451.495 | O9: =CH_RehabBasis*INDEX(CH_BurnCurve,13) -> 0 | P9: =CH_RehabBasis*INDEX(CH_BurnCurve,14) -> 0 | Q9: =CH_RehabBasis*INDEX(CH_BurnCurve,15) -> 0 | R9: =CH_RehabBasis*INDEX(CH_BurnCurve,16) -> 0 | S9: =CH_RehabBasis*INDEX(CH_BurnCurve,17) -> 0 | T9: =CH_RehabBasis*INDEX(CH_BurnCurve,18) -> 0 | U9: =SUM(C9:T9) -> 5443541.4
B10: Fees + COI + reserves (M1) | C10: =IF(C5=1,CH_FinFees+'Sources & Uses'!C21+'Sources & Uses'!C23,0) -> 554211.03 | D10: =IF(D5=1,CH_FinFees+'Sources & Uses'!C21+'Sources & Uses'!C23,0) -> 0 | E10: =IF(E5=1,CH_FinFees+'Sources & Uses'!C21+'Sources & Uses'!C23,0) -> 0 | F10: =IF(F5=1,CH_FinFees+'Sources & Uses'!C21+'Sources & Uses'!C23,0) -> 0 | G10: =IF(G5=1,CH_FinFees+'Sources & Uses'!C21+'Sources & Uses'!C23,0) -> 0 | H10: =IF(H5=1,CH_FinFees+'Sources & Uses'!C21+'Sources & Uses'!C23,0) -> 0 | I10: =IF(I5=1,CH_FinFees+'Sources & Uses'!C21+'Sources & Uses'!C23,0) -> 0 | J10: =IF(J5=1,CH_FinFees+'Sources & Uses'!C21+'Sources & Uses'!C23,0) -> 0 | K10: =IF(K5=1,CH_FinFees+'Sources & Uses'!C21+'Sources & Uses'!C23,0) -> 0 | L10: =IF(L5=1,CH_FinFees+'Sources & Uses'!C21+'Sources & Uses'!C23,0) -> 0 | M10: =IF(M5=1,CH_FinFees+'Sources & Uses'!C21+'Sources & Uses'!C23,0) -> 0 | N10: =IF(N5=1,CH_FinFees+'Sources & Uses'!C21+'Sources & Uses'!C23,0) -> 0 | O10: =IF(O5=1,CH_FinFees+'Sources & Uses'!C21+'Sources & Uses'!C23,0) -> 0 | P10: =IF(P5=1,CH_FinFees+'Sources & Uses'!C21+'Sources & Uses'!C23,0) -> 0 | Q10: =IF(Q5=1,CH_FinFees+'Sources & Uses'!C21+'Sources & Uses'!C23,0) -> 0 | R10: =IF(R5=1,CH_FinFees+'Sources & Uses'!C21+'Sources & Uses'!C23,0) -> 0 | S10: =IF(S5=1,CH_FinFees+'Sources & Uses'!C21+'Sources & Uses'!C23,0) -> 0 | T10: =IF(T5=1,CH_FinFees+'Sources & Uses'!C21+'Sources & Uses'!C23,0) -> 0 | U10: =SUM(C10:T10) -> 554211.03
B11: Cash developer fee (at stabilization) | C11: =IF(C5=CH_RehabMonths+6,CH_DevFee-CH_DDF,0) -> 0 | D11: =IF(D5=CH_RehabMonths+6,CH_DevFee-CH_DDF,0) -> 0 | E11: =IF(E5=CH_RehabMonths+6,CH_DevFee-CH_DDF,0) -> 0 | F11: =IF(F5=CH_RehabMonths+6,CH_DevFee-CH_DDF,0) -> 0 | G11: =IF(G5=CH_RehabMonths+6,CH_DevFee-CH_DDF,0) -> 0 | H11: =IF(H5=CH_RehabMonths+6,CH_DevFee-CH_DDF,0) -> 0 | I11: =IF(I5=CH_RehabMonths+6,CH_DevFee-CH_DDF,0) -> 0 | J11: =IF(J5=CH_RehabMonths+6,CH_DevFee-CH_DDF,0) -> 0 | ... T11: =IF(T5=CH_RehabMonths+6,CH_DevFee-CH_DDF,0) -> 0 | U11: =SUM(C11:T11) -> 0
B12: TOTAL USES (cash) | C12: =SUM(C7:C11) -> 646751.23 | D12: =SUM(D7:D11) -> 272177.07 | E12: =SUM(E7:E11) -> 432761.54 | F12: =SUM(F7:F11) -> 563950.89 | G12: =SUM(G7:G11) -> 656491.09 | H12: =SUM(H7:H11) -> 704394.25 | I12: =SUM(I7:I11) -> 704394.25 | J12: =SUM(J7:J11) -> 656491.09 | ... T12: =SUM(T7:T11) -> 0 | U12: =SUM(C12:T12) -> 5997752.4
B13: Equity tranches (from pay-in blocks) | C13: =SUMPRODUCT((CH_PayinMonths=C5)*CH_PayinAmts) -> 448373.62 | D13: =SUMPRODUCT((CH_PayinMonths=D5)*CH_PayinAmts) -> 0 | E13: =SUMPRODUCT((CH_PayinMonths=E5)*CH_PayinAmts) -> 0 | F13: =SUMPRODUCT((CH_PayinMonths=F5)*CH_PayinAmts) -> 0 | G13: =SUMPRODUCT((CH_PayinMonths=G5)*CH_PayinAmts) -> 0 | H13: =SUMPRODUCT((CH_PayinMonths=H5)*CH_PayinAmts) -> 0 | I13: =SUMPRODUCT((CH_PayinMonths=I5)*CH_PayinAmts) -> 0 | J13: =SUMPRODUCT((CH_PayinMonths=J5)*CH_PayinAmts) -> 0 | ... T13: =SUMPRODUCT((CH_PayinMonths=T5)*CH_PayinAmts) -> 672560.42 | U13: =SUM(C13:T13) -> 2241868.1
B14: Perm/bond draw (plug to need) | C14: =MAX(0,MIN(CH_SelProceeds-(0),(SUM($C12:C12)+SUM($C15:C15))-(SUM($C13:C13))-(0))) -> 198377.61 | D14: =MAX(0,MIN(CH_SelProceeds-(SUM($C14:C14)),(SUM($C12:D12)+SUM($C15:D15))-(SUM($C13:D13))-(SUM($C14:C14)))) -> 272177.07 | E14: =MAX(0,MIN(CH_SelProceeds-(SUM($C14:D14)),(SUM($C12:E12)+SUM($C15:E15))-(SUM($C13:E13))-(SUM($C14:D14)))) -> 434122.42 | F14: =MAX(0,MIN(CH_SelProceeds-(SUM($C14:E14)),(SUM($C12:F12)+SUM($C15:F15))-(SUM($C13:F13))-(SUM($C14:E14)))) -> 567489.19 | G14: =MAX(0,MIN(CH_SelProceeds-(SUM($C14:F14)),(SUM($C12:G12)+SUM($C15:G15))-(SUM($C13:G13))-(SUM($C14:F14)))) -> 662884.53 | H14: =MAX(0,MIN(CH_SelProceeds-(SUM($C14:G14)),(SUM($C12:H12)+SUM($C15:H15))-(SUM($C13:H13))-(SUM($C14:G14)))) -> 714134.08 | I14: =MAX(0,MIN(CH_SelProceeds-(SUM($C14:H14)),(SUM($C12:I12)+SUM($C15:I15))-(SUM($C13:I13))-(SUM($C14:H14)))) -> 561167.47 | J14: =MAX(0,MIN(CH_SelProceeds-(SUM($C14:I14)),(SUM($C12:J12)+SUM($C15:J15))-(SUM($C13:J13))-(SUM($C14:I14)))) -> 0 | K14: =MAX(0,MIN(CH_SelProceeds-(SUM($C14:J14)),(SUM($C12:K12)+SUM($C15:K15))-(SUM($C13:K13))-(SUM($C14:J14)))) -> 0 | ... T14: =MAX(0,MIN(CH_SelProceeds-(SUM($C14:S14)),(SUM($C12:T12)+SUM($C15:T15))-(SUM($C13:T13))-(SUM($C14:S14)))) -> 0 | U14: =SUM(C14:T14) -> 3410352.4
B15: Construction interest (capitalized) | C15: 0 | D15: =IF(D5<=CH_RehabMonths,MAX(0,C16-$C$16)*PermRate/12,0) -> 0 | E15: =IF(E5<=CH_RehabMonths,MAX(0,D16-$C$16)*PermRate/12,0) -> 1360.8853 | F15: =IF(F5<=CH_RehabMonths,MAX(0,E16-$C$16)*PermRate/12,0) -> 3538.3019 | G15: =IF(G5<=CH_RehabMonths,MAX(0,F16-$C$16)*PermRate/12,0) -> 6393.4393 | H15: =IF(H5<=CH_RehabMonths,MAX(0,G16-$C$16)*PermRate/12,0) -> 9739.8292 | I15: =IF(I5<=CH_RehabMonths,MAX(0,H16-$C$16)*PermRate/12,0) -> 13359.199 | J15: =IF(J5<=CH_RehabMonths,MAX(0,I16-$C$16)*PermRate/12,0) -> 16231.832 | K15: =IF(K5<=CH_RehabMonths,MAX(0,J16-$C$16)*PermRate/12,0) -> 16312.991 | ... T15: =IF(T5<=CH_RehabMonths,MAX(0,S16-$C$16)*PermRate/12,0) -> 0 | U15: =SUM(C15:T15) -> 116366.47
B16: Perm/bond outstanding balance | C16: =0+C14+C15 -> 198377.61 | D16: =C16+D14+D15 -> 470554.68 | E16: =D16+E14+E15 -> 906037.99 | F16: =E16+F14+F15 -> 1477065.5 | G16: =F16+G14+G15 -> 2146343.5 | H16: =G16+H14+H15 -> 2870217.4 | I16: =H16+I14+I15 -> 3444744 | J16: =I16+J14+J15 -> 3460975.9 | K16: =J16+K14+K15 -> 3477288.9 | ... T16: =S16+T14+T15 -> 3526718.8
B17: Cumulative funded (equity + perm) | C17: =SUM($C13:C13)+SUM($C14:C14) -> 646751.23 | D17: =SUM($C13:D13)+SUM($C14:D14) -> 918928.3 | E17: =SUM($C13:E13)+SUM($C14:E14) -> 1353050.7 | F17: =SUM($C13:F13)+SUM($C14:F14) -> 1920539.9 | G17: =SUM($C13:G13)+SUM($C14:G14) -> 2583424.4 | H17: =SUM($C13:H13)+SUM($C14:H14) -> 3297558.5 | I17: =SUM($C13:I13)+SUM($C14:I14) -> 3858726 | J17: =SUM($C13:J13)+SUM($C14:J14) -> 3858726 | ... T17: =SUM($C13:T13)+SUM($C14:T14) -> 5652220.5
B18: Max outstanding perm/bond balance | U18: =MAX(C16:T16) -> 3526718.8
B21: NEW ZION — close: | D21: =NZ_ResynDate -> 47119
B22: Month | C22: 1 | D22: 2 | E22: 3 | F22: 4 | G22: 5 | H22: 6 | I22: 7 | J22: 8 | K22: 9 | L22: 10 | M22: 11 | N22: 12 | O22: 13 | P22: 14 | Q22: 15 | R22: 16 | S22: 17 | T22: 18 | U22: TOTAL
B23: Calendar month | C23: =EDATE(NZ_ResynDate,0) -> 47119 | D23: =EDATE(NZ_ResynDate,1) -> 47150 | E23: =EDATE(NZ_ResynDate,2) -> 47178 | F23: =EDATE(NZ_ResynDate,3) -> 47209 | G23: =EDATE(NZ_ResynDate,4) -> 47239 | H23: =EDATE(NZ_ResynDate,5) -> 47270 | I23: =EDATE(NZ_ResynDate,6) -> 47300 | J23: =EDATE(NZ_ResynDate,7) -> 47331 | K23: =EDATE(NZ_ResynDate,8) -> 47362 | L23: =EDATE(NZ_ResynDate,9) -> 47392 | M23: =EDATE(NZ_ResynDate,10) -> 47423 | N23: =EDATE(NZ_ResynDate,11) -> 47453 | O23: =EDATE(NZ_ResynDate,12) -> 47484 | P23: =EDATE(NZ_ResynDate,13) -> 47515 | Q23: =EDATE(NZ_ResynDate,14) -> 47543 | R23: =EDATE(NZ_ResynDate,15) -> 47574 | S23: =EDATE(NZ_ResynDate,16) -> 47604 | T23: =EDATE(NZ_ResynDate,17) -> 47635
B24: Acquisition price (M1) | C24: =IF(C22=1,NZ_AcqPrice,0) -> 0 | D24: =IF(D22=1,NZ_AcqPrice,0) -> 0 | E24: =IF(E22=1,NZ_AcqPrice,0) -> 0 | F24: =IF(F22=1,NZ_AcqPrice,0) -> 0 | G24: =IF(G22=1,NZ_AcqPrice,0) -> 0 | H24: =IF(H22=1,NZ_AcqPrice,0) -> 0 | I24: =IF(I22=1,NZ_AcqPrice,0) -> 0 | J24: =IF(J22=1,NZ_AcqPrice,0) -> 0 | ... T24: =IF(T22=1,NZ_AcqPrice,0) -> 0 | U24: =SUM(C24:T24) -> 0
B25: NZ HOME payoff (M1) | C25: =IF(C22=1,NZ_HOMEPayoff,0) -> 2027484.6 | D25: =IF(D22=1,NZ_HOMEPayoff,0) -> 0 | E25: =IF(E22=1,NZ_HOMEPayoff,0) -> 0 | F25: =IF(F22=1,NZ_HOMEPayoff,0) -> 0 | G25: =IF(G22=1,NZ_HOMEPayoff,0) -> 0 | H25: =IF(H22=1,NZ_HOMEPayoff,0) -> 0 | I25: =IF(I22=1,NZ_HOMEPayoff,0) -> 0 | J25: =IF(J22=1,NZ_HOMEPayoff,0) -> 0 | ... T25: =IF(T22=1,NZ_HOMEPayoff,0) -> 0 | U25: =SUM(C25:T25) -> 2027484.6
