Workbook
Name AMFeeCap: QAP_Rule_Register!$H$23
Name ArchPct: QAP_Rule_Register!$H$16
Name BoostCapPct: QAP_Rule_Register!$H$10
Name BoostEligible: 'Dashboard Calc'!$B$6
Name BuilderOHPct: QAP_Rule_Register!$H$18
Name BuilderProfitPct: QAP_Rule_Register!$H$17
Name BuildingType: 'Dashboard Calc'!$B$10
Name CashFlowCeilPct: QAP_Rule_Register!$H$36
Name checks_paid: #N/A
Name ContingencyPct: QAP_Rule_Register!$H$20
Name CreditType: 'Dashboard Calc'!$B$5
Name DeferredFee: 'Dashboard Calc'!$B$13
Name DevFeeCapAbs: QAP_Rule_Register!$B$48
Name DevFeeCapPct: QAP_Rule_Register!$B$49
Name DSCR15Floor: QAP_Rule_Register!$B$54
Name DSCRCeil: QAP_Rule_Register!$B$53
Name DSCRFloor: QAP_Rule_Register!$B$52
Name EXP: #N/A
Name ExpTrendMin: QAP_Rule_Register!$H$30
Name GenReqPct: QAP_Rule_Register!$H$19
Name HUDTDCLimit: 'Dashboard Calc'!$B$12
Name MEMORANDUM: "memo1"
Name MGMT: #N/A
Name OpexMinPU: QAP_Rule_Register!$H$21
Name OpReserveFrac: QAP_Rule_Register!$H$22
Name Pool: 'Dashboard Calc'!$B$9
Name PoolCapMetro: QAP_Rule_Register!$B$44
Name PoolCapReproc: QAP_Rule_Register!$B$47
Name PoolCapRural: QAP_Rule_Register!$B$45
Name PoolCapRuralQNP: QAP_Rule_Register!$B$46
Name ProjectName: 'Dashboard Calc'!$B$3
Name ProjectType: 'Dashboard Calc'!$B$4
Name RDHUD: 'Dashboard Calc'!$B$7
Name RENT: #N/A
Name RentTrendMax: QAP_Rule_Register!$H$28
Name ReserveFloorFamily: QAP_Rule_Register!$B$42
Name ReserveFloorRehab: QAP_Rule_Register!$B$43
Name ReserveFloorSenior: QAP_Rule_Register!$B$41
Name SUBalanceTol: QAP_Rule_Register!$H$32
Name SyndCapPriv: QAP_Rule_Register!$B$50
Name SyndCapPub: QAP_Rule_Register!$B$51
Name Syndication: 'Dashboard Calc'!$B$8
Name VAC: #N/A
Name VacancyMin: QAP_Rule_Register!$H$26

Sheet Model Scorecard
A1: ='Dashboard Calc'!B3&" Scorecard" -> Westbend Scorecard
A2: Metric | B2: Value | C2: Test | D2: Threshold | E2: Status | F2: Severity
A3: DSCR
A4: ='Dashboard Calc'!M9 -> Annual DSCR band (Yr2-17) | B4: ='Dashboard Calc'!N9 -> 1.2459969 | C4: band | D4: ='Dashboard Calc'!O9 -> 1.15-1.40 | E4: ='Dashboard Calc'!P9 -> FAIL | F4: =IF('Dashboard Calc'!P9<>"FAIL","",IF('Dashboard Calc'!Q9="error","Hard fail",IF('Dashboard Calc'!Q9="warning","Warning","Info"))) -> Hard fail
A5: ='Dashboard Calc'!M10 -> 15-yr projected DSCR (y5/10/15) | B5: ='Dashboard Calc'!N10 -> 1.2640715 | C5: band | D5: ='Dashboard Calc'!O10 -> 1.00-1.40 | E5: ='Dashboard Calc'!P10 -> FAIL | F5: =IF('Dashboard Calc'!P10<>"FAIL","",IF('Dashboard Calc'!Q10="error","Hard fail",IF('Dashboard Calc'!Q10="warning","Warning","Info"))) -> Hard fail
A6: CASH FLOW & DEFERRED FEE
A7: ='Dashboard Calc'!M29 -> Year-1 cash-flow ceiling | B7: ='Dashboard Calc'!N29 -> 274844.28 | C7: ≤ | D7: ='Dashboard Calc'!O29 -> 133198.81 | E7: ='Dashboard Calc'!P29 -> FAIL | F7: =IF('Dashboard Calc'!P29<>"FAIL","",IF('Dashboard Calc'!Q29="error","Hard fail",IF('Dashboard Calc'!Q29="warning","Warning","Info"))) -> Warning
A8: ='Dashboard Calc'!M30 -> Deferred dev-fee payoff by Yr15 | B8: ='Dashboard Calc'!N30 -> 3865332.1 | C8: ≥ | D8: ='Dashboard Calc'!O30 -> 2131813.1 | E8: ='Dashboard Calc'!P30 -> PASS | F8: =IF('Dashboard Calc'!P30<>"FAIL","",IF('Dashboard Calc'!Q30="error","Hard fail",IF('Dashboard Calc'!Q30="warning","Warning","Info")))
A9: COST & TDC
A10: ='Dashboard Calc'!M35 -> Per-unit TDC vs QAP max | B10: ='Dashboard Calc'!N35 -> 181600.1 | C10: ≤ | D10: ='Dashboard Calc'!O35 -> 247226.11 | E10: ='Dashboard Calc'!P35 -> PASS | F10: =IF('Dashboard Calc'!P35<>"FAIL","",IF('Dashboard Calc'!Q35="error","Hard fail",IF('Dashboard Calc'!Q35="warning","Warning","Info")))
A11: ='Dashboard Calc'!M36 -> Total TDC vs QAP max | B11: ='Dashboard Calc'!N36 -> 50848028 | C11: ≤ | D11: ='Dashboard Calc'!O36 -> 69223310 | E11: ='Dashboard Calc'!P36 -> PASS | F11: =IF('Dashboard Calc'!P36<>"FAIL","",IF('Dashboard Calc'!Q36="error","Hard fail",IF('Dashboard Calc'!Q36="warning","Warning","Info")))
A12: ='Dashboard Calc'!M26 -> HUD Total Dev Cost limit | B12: ='Dashboard Calc'!N26 -> 50848028 | C12: ≤ | D12: ='Dashboard Calc'!O26 -> 69223310 | E12: ='Dashboard Calc'!P26 -> PASS | F12: =IF('Dashboard Calc'!P26<>"FAIL","",IF('Dashboard Calc'!Q26="error","Hard fail",IF('Dashboard Calc'!Q26="warning","Warning","Info")))
A13: FEE LIMITS
A14: ='Dashboard Calc'!M11 -> Developer fee | B14: ='Dashboard Calc'!N11 -> 5921703 | C14: ≤ | D14: ='Dashboard Calc'!O11 -> No cap (4% bond) | E14: ='Dashboard Calc'!P11 -> PASS | F14: =IF('Dashboard Calc'!P11<>"FAIL","",IF('Dashboard Calc'!Q11="error","Hard fail",IF('Dashboard Calc'!Q11="warning","Warning","Info")))
A15: ='Dashboard Calc'!M12 -> Architect / design fee | B15: ='Dashboard Calc'!N12 -> 750000 | C15: ≤ | D15: ='Dashboard Calc'!O12 -> 2440288.8 | E15: ='Dashboard Calc'!P12 -> PASS | F15: =IF('Dashboard Calc'!P12<>"FAIL","",IF('Dashboard Calc'!Q12="error","Hard fail",IF('Dashboard Calc'!Q12="warning","Warning","Info")))
A16: ='Dashboard Calc'!M13 -> Builder profit | B16: ='Dashboard Calc'!N13 -> 1834803.6 | C16: ≤ | D16: ='Dashboard Calc'!O13 -> 1834803.6 | E16: ='Dashboard Calc'!P13 -> PASS | F16: =IF('Dashboard Calc'!P13<>"FAIL","",IF('Dashboard Calc'!Q13="error","Hard fail",IF('Dashboard Calc'!Q13="warning","Warning","Info")))
A17: ='Dashboard Calc'!M14 -> Builder overhead | B17: ='Dashboard Calc'!N14 -> 611601.21 | C17: ≤ | D17: ='Dashboard Calc'!O14 -> 611601.21 | E17: ='Dashboard Calc'!P14 -> PASS | F17: =IF('Dashboard Calc'!P14<>"FAIL","",IF('Dashboard Calc'!Q14="error","Hard fail",IF('Dashboard Calc'!Q14="warning","Warning","Info")))
A18: ='Dashboard Calc'!M15 -> General requirements | B18: ='Dashboard Calc'!N15 -> 1834803.6 | C18: ≤ | D18: ='Dashboard Calc'!O15 -> 1834803.6 | E18: ='Dashboard Calc'!P15 -> PASS | F18: =IF('Dashboard Calc'!P15<>"FAIL","",IF('Dashboard Calc'!Q15="error","Hard fail",IF('Dashboard Calc'!Q15="warning","Warning","Info")))
A19: ='Dashboard Calc'!M16 -> Construction contingency | B19: ='Dashboard Calc'!N16 -> 1660060.4 | C19: ≤ | D19: ='Dashboard Calc'!O16 -> 3486126.9 | E19: ='Dashboard Calc'!P16 -> PASS | F19: =IF('Dashboard Calc'!P16<>"FAIL","",IF('Dashboard Calc'!Q16="error","Hard fail",IF('Dashboard Calc'!Q16="warning","Warning","Info")))
A20: OPERATING & RESERVES
A21: ='Dashboard Calc'!M17 -> Minimum operating expenses | B21: ='Dashboard Calc'!N17 -> 1331988.1 | C21: ≥ | D21: ='Dashboard Calc'!O17 -> 1260000 | E21: ='Dashboard Calc'!P17 -> PASS | F21: =IF('Dashboard Calc'!P17<>"FAIL","",IF('Dashboard Calc'!Q17="error","Hard fail",IF('Dashboard Calc'!Q17="warning","Warning","Info")))
A22: ='Dashboard Calc'!M18 -> Operating reserve (6 mo) | B22: ='Dashboard Calc'!N18 -> 665994.03 | C22: ≥ | D22: ='Dashboard Calc'!O18 -> 665994.03 | E22: ='Dashboard Calc'!P18 -> PASS | F22: =IF('Dashboard Calc'!P18<>"FAIL","",IF('Dashboard Calc'!Q18="error","Hard fail",IF('Dashboard Calc'!Q18="warning","Warning","Info")))
A23: ='Dashboard Calc'!M20 -> Repl-reserve adequacy (all yrs) | B23: ='Dashboard Calc'!N20 -> 500 | C23: ≥ | D23: ='Dashboard Calc'!O20 -> 350 | E23: ='Dashboard Calc'!P20 -> PASS | F23: =IF('Dashboard Calc'!P20<>"FAIL","",IF('Dashboard Calc'!Q20="error","Hard fail",IF('Dashboard Calc'!Q20="warning","Warning","Info")))
A24: VACANCY & TRENDING
A25: ='Dashboard Calc'!M21 -> Vacancy, years 1-3 | B25: ='Dashboard Calc'!N21 -> 0.07 | C25: ≥ | D25: ='Dashboard Calc'!O21 -> 0.07 | E25: ='Dashboard Calc'!P21 -> PASS | F25: =IF('Dashboard Calc'!P21<>"FAIL","",IF('Dashboard Calc'!Q21="error","Hard fail",IF('Dashboard Calc'!Q21="warning","Warning","Info")))
A26: ='Dashboard Calc'!M22 -> Vacancy, years 4+ | B26: ='Dashboard Calc'!N22 -> 0.07 | C26: ≥ | D26: ='Dashboard Calc'!O22 -> 0.07 | E26: ='Dashboard Calc'!P22 -> PASS | F26: =IF('Dashboard Calc'!P22<>"FAIL","",IF('Dashboard Calc'!Q22="error","Hard fail",IF('Dashboard Calc'!Q22="warning","Warning","Info")))
A27: ='Dashboard Calc'!M23 -> Rent inflation, years 1-3 | B27: ='Dashboard Calc'!N23 -> 0.02 | C27: ≤ | D27: ='Dashboard Calc'!O23 -> 0.02 | E27: ='Dashboard Calc'!P23 -> PASS | F27: =IF('Dashboard Calc'!P23<>"FAIL","",IF('Dashboard Calc'!Q23="error","Hard fail",IF('Dashboard Calc'!Q23="warning","Warning","Info")))
A28: ='Dashboard Calc'!M24 -> Rent inflation, years 4-15 | B28: ='Dashboard Calc'!N24 -> 0.02 | C28: ≤ | D28: ='Dashboard Calc'!O24 -> 0.02 | E28: ='Dashboard Calc'!P24 -> PASS | F28: =IF('Dashboard Calc'!P24<>"FAIL","",IF('Dashboard Calc'!Q24="error","Hard fail",IF('Dashboard Calc'!Q24="warning","Warning","Info")))
A29: ='Dashboard Calc'!M25 -> Expense inflation (payroll YoY) | B29: ='Dashboard Calc'!N25 -> 0.03 | C29: ≥ | D29: ='Dashboard Calc'!O25 -> 0.028 | E29: ='Dashboard Calc'!P25 -> PASS | F29: =IF('Dashboard Calc'!P25<>"FAIL","",IF('Dashboard Calc'!Q25="error","Hard fail",IF('Dashboard Calc'!Q25="warning","Warning","Info")))
A30: CREDIT STRUCTURE & SIZING
A31: ='Dashboard Calc'!M3 -> 4% credit requires bonds | B31: ='Dashboard Calc'!N3 -> 26629504 | C31: > | D31: ='Dashboard Calc'!O3 -> Bonds > $0 | E31: ='Dashboard Calc'!P3 -> PASS | F31: =IF('Dashboard Calc'!P3<>"FAIL","",IF('Dashboard Calc'!Q3="error","Hard fail",IF('Dashboard Calc'!Q3="warning","Warning","Info")))
A32: ='Dashboard Calc'!M4 -> 9% + bonds mutually exclusive | B32: ='Dashboard Calc'!N4 -> n/a | C32: = | D32: ='Dashboard Calc'!O4 -> Bonds = $0 | E32: ='Dashboard Calc'!P4 -> N/A | F32: =IF('Dashboard Calc'!P4<>"FAIL","",IF('Dashboard Calc'!Q4="error","Hard fail",IF('Dashboard Calc'!Q4="warning","Warning","Info")))
A33: ='Dashboard Calc'!M5 -> Construction basis boost cap | B33: ='Dashboard Calc'!N5 -> 0 | C33: ≤ | D33: ='Dashboard Calc'!O5 -> 0.3 | E33: ='Dashboard Calc'!P5 -> PASS | F33: =IF('Dashboard Calc'!P5<>"FAIL","",IF('Dashboard Calc'!Q5="error","Hard fail",IF('Dashboard Calc'!Q5="warning","Warning","Info")))
A34: ='Dashboard Calc'!M6 -> Basis-boost geo eligibility | B34: ='Dashboard Calc'!N6 -> No | C34: req | D34: ='Dashboard Calc'!O6 -> Qualifying geo | E34: ='Dashboard Calc'!P6 -> PASS | F34: =IF('Dashboard Calc'!P6<>"FAIL","",IF('Dashboard Calc'!Q6="error","Hard fail",IF('Dashboard Calc'!Q6="warning","Warning","Info")))
A35: ='Dashboard Calc'!M7 -> Per-project pool cap | B35: ='Dashboard Calc'!N7 -> n/a | C35: ≤ | D35: ='Dashboard Calc'!O7 -> N/A (PAB cap) | E35: ='Dashboard Calc'!P7 -> N/A | F35: =IF('Dashboard Calc'!P7<>"FAIL","",IF('Dashboard Calc'!Q7="error","Hard fail",IF('Dashboard Calc'!Q7="warning","Warning","Info")))
A36: ='Dashboard Calc'!M8 -> Maximum allowable credit | B36: ='Dashboard Calc'!N8 -> 1841756.5 | C36: ≤ | D36: ='Dashboard Calc'!O8 -> 1841756.5 | E36: ='Dashboard Calc'!P8 -> PASS | F36: =IF('Dashboard Calc'!P8<>"FAIL","",IF('Dashboard Calc'!Q8="error","Hard fail",IF('Dashboard Calc'!Q8="warning","Warning","Info")))
A38: VERDICT KEY
A39: FAIL — one or more hard fails present
A40: MARGINAL — no hard fails, but ≥1 warning or pending item
A41: PENCILS — fully clean: no hard fails, warnings, or pending items

Sheet Unit Mix+Rents
A1: UNIT MIX
A3: # BRs | B3: # Baths | C3: Sqft | D3: # Units | E3: LIHTC | F3: Staff Unit | G3: Subsidy | H3: PSH | I3: % AMI | J3: Net Rent | K3: Gr Rent | L3: UA | O3: Unit Ratio
A4: 1 | B4: 1 | C4: 900 | D4: 0 | E4: Yes | F4: No | G4: No | H4: No | I4: 0.2 | J4: =+K4-L4 -> 270 | K4: =+VLOOKUP(I4,$A$20:$F$27,A4+2,FALSE) -> 337 | L4: =HLOOKUP(A4,$B$32:$F$37,6,TRUE) -> 67 | O4: =+D4/$D$14 -> 0
A5: 1 | B5: 1 | C5: 900 | D5: 0 | E5: Yes | F5: No | G5: No | H5: No | I5: 0.3 | J5: =+K5-L5 -> 431 | K5: =+VLOOKUP(I5,$A$20:$F$27,A5+2,FALSE) -> 498 | L5: =HLOOKUP(A5,$B$32:$F$37,6,TRUE) -> 67 | O5: =+D5/$D$14 -> 0
A6: 1 | B6: 1 | C6: 900 | D6: 0 | E6: Yes | F6: No | G6: No | H6: No | I6: 0.4 | J6: =+K6-L6 -> 607 | K6: =+VLOOKUP(I6,$A$20:$F$27,A6+2,FALSE) -> 674 | L6: =HLOOKUP(A6,$B$32:$F$37,6,TRUE) -> 67 | O6: =+D6/$D$14 -> 0
A7: 1 | B7: 1 | C7: 900 | D7: 0 | E7: Yes | F7: No | G7: No | H7: No | I7: 0.5 | J7: =+K7-L7 -> 764 | K7: =+VLOOKUP(I7,$A$20:$F$27,A7+2,FALSE) -> 831 | L7: =HLOOKUP(A7,$B$32:$F$37,6,TRUE) -> 67 | O7: =+D7/$D$14 -> 0
A8: 1 | B8: 1 | C8: 900 | D8: 110 | E8: Yes | F8: No | G8: No | H8: No | I8: 0.6 | J8: =+K8-L8 -> 930 | K8: =+VLOOKUP(I8,$A$20:$F$27,A8+2,FALSE) -> 997 | L8: =HLOOKUP(A8,$B$32:$F$37,6,TRUE) -> 67 | O8: =+D8/$D$14 -> 0.39285714
A9: 2 | B9: 2 | C9: 1100 | D9: 0 | E9: Yes | F9: No | G9: No | H9: No | I9: 0.2 | J9: =+K9-L9 -> 315 | K9: =+VLOOKUP(I9,$A$20:$F$27,A9+2,FALSE) -> 404 | L9: =HLOOKUP(A9,$B$32:$F$37,6,TRUE) -> 89 | O9: =+D9/$D$14 -> 0
A10: 2 | B10: 2 | C10: 1100 | D10: 0 | E10: Yes | F10: No | G10: No | H10: No | I10: 0.3 | J10: =+K10-L10 -> 509 | K10: =+VLOOKUP(I10,$A$20:$F$27,A10+2,FALSE) -> 598 | L10: =HLOOKUP(A10,$B$32:$F$37,6,TRUE) -> 89 | O10: =+D10/$D$14 -> 0
A11: 2 | B11: 2 | C11: 1100 | D11: 0 | E11: Yes | F11: No | G11: No | H11: No | I11: 0.4 | J11: =+K11-L11 -> 720 | K11: =+VLOOKUP(I11,$A$20:$F$27,A11+2,FALSE) -> 809 | L11: =HLOOKUP(A11,$B$32:$F$37,6,TRUE) -> 89 | O11: =+D11/$D$14 -> 0
A12: 2 | B12: 2 | C12: 1100 | D12: 0 | E12: Yes | F12: No | G12: No | H12: No | I12: 0.5 | J12: =+K12-L12 -> 908 | K12: =+VLOOKUP(I12,$A$20:$F$27,A12+2,FALSE) -> 997 | L12: =HLOOKUP(A12,$B$32:$F$37,6,TRUE) -> 89 | O12: =+D12/$D$14 -> 0
A13: 2 | B13: 2 | C13: 1100 | D13: 170 | E13: Yes | F13: No | G13: No | H13: No | I13: 0.6 | J13: =+K13-L13 -> 1108 | K13: =+VLOOKUP(I13,$A$20:$F$27,A13+2,FALSE) -> 1197 | L13: =HLOOKUP(A13,$B$32:$F$37,6,TRUE) -> 89 | O13: =+D13/$D$14 -> 0.60714286
A14: TOTAL | C14: =+SUMPRODUCT(C4:C13,D4:D13) -> 286000 | D14: =+SUM(D4:D13) -> 280 | I14: =+SUMPRODUCT(I4:I13,O4:O13) -> 0.6 | J14: =+SUMPRODUCT(D4:D13,J4:J13) -> 290660 | K14: =+SUMPRODUCT(D4:D13,K4:K13) -> 313160 | L14: =+SUMPRODUCT(D4:D13,L4:L13) -> 22500
A16: 2025 New Orleans-Metairie MSA Gross Rent Limits
A17: Source: HUD FY2025 MTSP Income Limits (Orleans Parish)
B19: 0 | C19: 1 | D19: 2 | E19: 3 | F19: 4
A20: 1.2 | B20: 1887 | C20: 2022 | D20: 2427 | E20: 2802 | F20: 3126
A21: 0.2 | B21: 314 | C21: 337 | D21: 404 | E21: 467 | F21: 521
A22: 0.3 | B22: 471 | C22: 498 | D22: 598 | E22: 691 | F22: 781
A23: 0.4 | B23: 629 | C23: 674 | D23: 809 | E23: 934 | F23: 1042
A24: 0.5 | B24: 786 | C24: 831 | D24: 997 | E24: 1151 | F24: 1302
A25: 0.6 | B25: 943 | C25: 997 | D25: 1197 | E25: 1382 | F25: 1563
A26: 0.7 | B26: 1100 | C26: 1163 | D26: 1396 | E26: 1612 | F26: 1823
A27: 0.8 | B27: 1258 | C27: 1348 | D27: 1618 | E27: 1868 | F27: 2084
A29: New Orleans Utility Allowances
A30: Source: HANO Utility Allowance Schedule, eff. 09/01/2025 (Apartment, all-electric)
B32: 0 | C32: 1 | D32: 2 | E32: 3 | F32: 4
A33: Electricity | B33: =8+5+18+15+11 -> 57 | C33: =9+6+21+18+13 -> 67 | D33: =11+8+30+24+16 -> 89 | E33: =12+11+38+31+19 -> 111 | F33: =14+13+46+38+23 -> 134
A34: Water | B34: 0 | C34: 0 | D34: 0 | E34: 0 | F34: 0
A35: Sewer | B35: 0 | C35: 0 | D35: 0 | E35: 0 | F35: 0
A36: Trash | B36: 0 | C36: 0 | D36: 0 | E36: 0 | F36: 0
A37: Total | B37: =+SUM(B33:B36) -> 57 | C37: =+SUM(C33:C36) -> 67 | D37: =+SUM(D33:D36) -> 89 | E37: =+SUM(E33:E36) -> 111 | F37: =+SUM(F33:F36) -> 134
A40: Checks
A42: % of Rental Subsidy Units in the project:
A43: % of Low-Income Units in the project:
A44: Total square feet for LIHTC units:
A45: PSH Units:
A46: Non-PSH Units Under 30% AMI:
A47: Units under 30% AMI:
A48: Units under 20% AMI:
...

Sheet Expense Detail
A1: EXPENSE DETAIL
A4: Staff Payroll
D5: # | E5: $/hr | F5: Per Year | G5: PUPA
B6: Property Manager | D6: 1 | E6: 24 | F6: =+D6*E6*2080 -> 49920 | G6: =+F6/'Unit Mix+Rents'!$D$14 -> 178.28571
B7: Leasing Agent | D7: 1 | E7: 18 | F7: =+D7*E7*2080 -> 37440 | G7: =+F7/'Unit Mix+Rents'!$D$14 -> 133.71429
B8: Maintenance Staff | D8: 2 | E8: 20 | F8: =+D8*E8*2080 -> 83200 | G8: =+F8/'Unit Mix+Rents'!$D$14 -> 297.14286
B10: Tax Burden | E10: 0.1 | F10: =+E10*SUM(F6:F8) -> 17056 | G10: =+F10/'Unit Mix+Rents'!$D$14 -> 60.914286
B11: Benefits Burden | E11: 0 | F11: =+E11*SUM(F6:F8) -> 0 | G11: =+F11/'Unit Mix+Rents'!$D$14 -> 0
A13: Total Payroll | F13: =+SUM(F6:F12) -> 187616 | G13: =+SUM(G6:G12) -> 670.05714
A15: Maintenance + Make Ready
D16: #/Mo | E16: $/Turn | F16: Per Year | G16: PUPA
B17: Make Ready | C17: 0.4 | D17: =+('Unit Mix+Rents'!D14*C17/12) -> 9.3333333 | E17: 400 | F17: =+D17*E17*12 -> 44800 | G17: =+F17/'Unit Mix+Rents'!$D$14 -> 160
E18: $/Unit/Mo | F18: Per Year | G18: PUPA
B19: Maintenance | E19: 50 | F19: =+E19*'Unit Mix+Rents'!D14*12 -> 168000 | G19: =+F19/'Unit Mix+Rents'!$D$14 -> 600
A20: Total Maintenance + Make Ready | F20: =+F17+F19 -> 212800 | G20: =+G17+G19 -> 760
A22: Utilities
E23: $/Unit/Mo | F23: Per Year | G23: PUPA
B24: Units
B25: Water | E25: 20 | F25: =+E25*'Unit Mix+Rents'!$D$14*12 -> 67200 | G25: =+F25/'Unit Mix+Rents'!$D$14 -> 240
B26: Sewer | C26: 2 | E26: =+E25*C26 -> 40 | F26: =+E26*'Unit Mix+Rents'!$D$14*12 -> 134400 | G26: =+F26/'Unit Mix+Rents'!$D$14 -> 480
B27: Gas | E27: 0 | F27: =+E27*'Unit Mix+Rents'!$D$14*12 -> 0 | G27: =+F27/'Unit Mix+Rents'!$D$14 -> 0
B28: Electricty | E28: 0 | F28: =+E28*'Unit Mix+Rents'!$D$14*12 -> 0 | G28: =+F28/'Unit Mix+Rents'!$D$14 -> 0
B29: Clubhouse
B30: Water | E30: 20 | F30: =+E30*12 -> 240 | G30: =+F30/'Unit Mix+Rents'!$D$14 -> 0.85714286
B31: Sewer | E31: =+E30*C26 -> 40 | F31: =+E31*12 -> 480 | G31: =+F31/'Unit Mix+Rents'!$D$14 -> 1.7142857
B32: Gas | E32: 0 | F32: =+E32*12 -> 0 | G32: =+F32/'Unit Mix+Rents'!$D$14 -> 0
B33: Electricty | E33: 300 | F33: =+E33*12 -> 3600 | G33: =+F33/'Unit Mix+Rents'!$D$14 -> 12.857143
B34: Property
B35: Water | E35: 50 | F35: =+E35*12 -> 600 | G35: =+F35/'Unit Mix+Rents'!$D$14 -> 2.1428571
B36: Sewer | E36: =+E35*C26 -> 100 | F36: =+E36*12 -> 1200 | G36: =+F36/'Unit Mix+Rents'!$D$14 -> 4.2857143
B37: Gas | E37: 0 | F37: =+E37*12 -> 0 | G37: =+F37/'Unit Mix+Rents'!$D$14 -> 0
B38: Electricty | E38: 200 | F38: =+E38*12 -> 2400 | G38: =+F38/'Unit Mix+Rents'!$D$14 -> 8.5714286
A39: Total Utilities | E39: =+F39/12/'Unit Mix+Rents'!D14 -> 62.535714 | F39: =+SUM(F25:F38) -> 210120 | G39: =+SUM(G25:G38) -> 750.42857
A41: Contract Services
E42: $/Mo | F42: Per Year | G42: PUPA
B43: Landscaping | E43: 1500 | F43: =+E43*12 -> 18000 | G43: =+F43/'Unit Mix+Rents'!$D$14 -> 64.285714
B44: Elevator Maintenance | E44: 0 | F44: =+E44*12 -> 0 | G44: =+F44/'Unit Mix+Rents'!$D$14 -> 0
B45: Pest Control | E45: 500 | F45: =+E45*12 -> 6000 | G45: =+F45/'Unit Mix+Rents'!$D$14 -> 21.428571
B46: Janitorial | E46: 500 | F46: =+E46*12 -> 6000 | G46: =+F46/'Unit Mix+Rents'!$D$14 -> 21.428571
B47: Security | E47: 500 | F47: =+E47*12 -> 6000 | G47: =+F47/'Unit Mix+Rents'!$D$14 -> 21.428571
...

Sheet Construction Estimates
A1: Construction Cost Estimates
A3: Category | D3: Unit Type | E3: Unit Cost | F3: Units | G3: Estimate
A4: Sitework | D4: lump sum | E4: 500000 | F4: 1 | G4: =E4*F4 -> 500000
A5: Abatement | D5: lump sum | E5: 0 | F5: 1 | G5: =E5*F5 -> 0
A6: Demolition | D6: $/unit | E6: 1500 | F6: =+'Unit Mix+Rents'!D14 -> 280 | G6: =E6*F6 -> 420000
A7: Construction Cost - Units | D7: $/unit | E7: 100000 | F7: =+'Unit Mix+Rents'!D14 -> 280 | G7: =(E7*F7)-G8-G10-G11-G12 -> 27575000
A8: Construction Cost - Clubhouse | D8: lump sum | E8: 200000 | F8: 1 | G8: =E8*F8 -> 200000
A9: Elevators | D9: $/shaft | E9: 0 | F9: 0 | G9: =E9*F9 -> 0
A10: Pool | D10: lump sum | E10: 100000 | F10: 1 | G10: =E10*F10 -> 100000
A11: Sports Courts | D11: lump sum | E11: 25000 | F11: 1 | G11: =E11*F11 -> 25000
A12: Playground | D12: lump sum | E12: 100000 | F12: 1 | G12: =E12*F12 -> 100000
A13: Total Vertical Construction Cost | G13: =SUM(G4:G12) -> 28920000
A14: General Requirements | D14: $/sf | G14: ='Sources & Uses'!I38 -> 1834803.6
A15: Overhead | D15: $/sf | G15: ='Sources & Uses'!I39 -> 611601.21
A16: Profit | D16: $/sf | G16: ='Sources & Uses'!I40 -> 1834803.6
A17: Contigency | D17: $/sf | G17: ='Sources & Uses'!I41 -> 1660060.4
A18: Total Hard Construction Cost | G18: =SUM(G13:G17) -> 34861269
A19: *Acquisition/Rehab: $110,000/unit direct hard cost; GC fees & contingency layered on top
A21: Vertical Cost per Unit | G21: =G13/'Unit Mix+Rents'!D14 -> 103285.71
A22: Hard Cost per Unit | G22: =+G18/'Unit Mix+Rents'!D14 -> 124504.53
A23: Vertical Cost per SF | G23: N/A
A24: Hard Cost per SF | G24: N/A
A26: Construction Cash Burn % by month
B28: Cumul | C28: Monthly
A29: M0 | B29: 0 | C29: =+B29 -> 0
A30: M1 | B30: =+B29+C30 -> 0.02 | C30: 0.02
A31: M2 | B31: =+B30+C31 -> 0.055 | C31: 0.035
A32: M3 | B32: =+B31+C32 -> 0.105 | C32: 0.05
A33: M4 | B33: =+B32+C33 -> 0.17 | C33: 0.065
A34: M5 | B34: =+B33+C34 -> 0.24 | C34: 0.07
A35: M6 | B35: =+B34+C35 -> 0.315 | C35: 0.075
A36: M7 | B36: =+B35+C36 -> 0.39 | C36: 0.075
A37: M8 | B37: =+B36+C37 -> 0.465 | C37: 0.075
A38: M9 | B38: =+B37+C38 -> 0.54 | C38: 0.075
A39: M10 | B39: =+B38+C39 -> 0.615 | C39: 0.075
A40: M11 | B40: =+B39+C40 -> 0.685 | C40: 0.07
A41: M12 | B41: =+B40+C41 -> 0.755 | C41: 0.07
... A47: M18 | B47: =+B46+C47 -> 1 | C47: 0.02

Sheet Sources & Uses
A1: SOURCES AND USES
A4: Debt/Equity Ratio | G4: Debt | I4: Equity
G6: =+I12/I26 -> 0.52370769 | I6: =+SUM(I14,I19,I24)/I26 -> 0.47629231
A8: Sources of Funds | E8: % of Tot Sources
B10: Series 2026 Permanent Bonds | E10: =+I10/$I$26 -> 0.52370769 | G10: =+I10/'Unit Mix+Rents'!$D$14 -> 95105.37 | I10: =+'S&U Timing'!D10 -> 26629504
B12: Total Loan/Bond Par Amount | E12: =+I12/$I$26 -> 0.52370769 | G12: =+I12/'Unit Mix+Rents'!$D$14 -> 95105.37 | I12: =+SUM(I10:I10) -> 26629504
B14: Tax Credit Equity | E14: =+I14/$I$26 -> 0.28686877 | G14: =+I14/'Unit Mix+Rents'!$D$14 -> 52095.398 | I14: =+'Tax Credit Calc'!F41 -> 14586712
B16: CDBG | E16: =+I16/$I$26 -> 0.14749834 | G16: =+I16/'Unit Mix+Rents'!$D$14 -> 26785.714 | I16: 7500000
B17: LHC HOME | E17: =+I17/$I$26 -> 0 | G17: =+I17/'Unit Mix+Rents'!$D$14 -> 0 | I17: 0
B19: Total Soft Money | E19: =+I19/$I$26 -> 0.14749834 | G19: =+I19/'Unit Mix+Rents'!$D$14 -> 26785.714 | I19: =+SUM(I16:I17) -> 7500000
B21: Deferred GC Fee | E21: =+I21/$I$26 -> 0 | G21: =+I21/'Unit Mix+Rents'!$D$14 -> 0 | I21: 0
B22: Deferred Developer Fee | D22: 0.36 | E22: =+I22/$I$26 -> 0.041925187 | G22: =+I22/'Unit Mix+Rents'!$D$14 -> 7613.6181 | I22: =+D22*I65 -> 2131813.1
B24: Total Deferred Fees | E24: =+I24/$I$26 -> 0.041925187 | G24: =+I24/'Unit Mix+Rents'!$D$14 -> 7613.6181 | I24: =+SUM(I21:I22) -> 2131813.1
A26: Total Sources of Funds | E26: =+I26/$I$26 -> 1 | G26: =+I26/'Unit Mix+Rents'!$D$14 -> 181600.1 | I26: =+SUM(I12,I14,I19,I24) -> 50848028
A28: Uses of Funds | E28: % of Tot Uses | G28: Per Unit | I28: Total
B30: Land/Building Acquisition Cost | E30: =+I30/$I$78 -> 0.078665784 | G30: =+I30/'Unit Mix+Rents'!$D$14 -> 14285.714 | I30: 4000000
B32: Construction Costs | E32: =+I32/$I$78 -> 0
B34: On-Site Improvements | E34: =+I34/$I$78 -> 0.009833223 | G34: =+I34/'Unit Mix+Rents'!$D$14 -> 1785.7143 | I34: ='Construction Estimates'!G4 -> 500000
B35: Special Site Conditions | E35: =+I35/$I$78 -> 0 | G35: =+I35/'Unit Mix+Rents'!$D$14 -> 0 | I35: =+'Construction Estimates'!G5 -> 0
B36: Residential Structures | E36: =+I36/$I$78 -> 0.55056215 | G36: =+I36/'Unit Mix+Rents'!$D$14 -> 99982.143 | I36: =+SUM('Construction Estimates'!G6,'Construction Estimates'!G7) -> 27995000
B37: Community Facilities | E37: =+I37/$I$78 -> 0.0083582395 | G37: =+I37/'Unit Mix+Rents'!$D$14 -> 1517.8571 | I37: =+SUM('Construction Estimates'!G8,'Construction Estimates'!G10,'Construction Estimates'!G11,'Construction Estimates'!G12) -> 425000
B38: General Requirements | D38: 0.06 | E38: =+I38/$I$78 -> 0.036084066 | G38: =+I38/'Unit Mix+Rents'!$D$14 -> 6552.8701 | I38: =+D38*I81 -> 1834803.6
B39: GC Overhead | D39: 0.02 | E39: =+I39/$I$78 -> 0.012028022 | G39: =+I39/'Unit Mix+Rents'!$D$14 -> 2184.29 | I39: =+D39*I81 -> 611601.21
B40: GC Profit | D40: 0.06 | E40: =+I40/$I$78 -> 0.036084066 | G40: =+I40/'Unit Mix+Rents'!$D$14 -> 6552.8701 | I40: =+D40*I81 -> 1834803.6
B41: Contingency (belongs to the GC) | D41: 0.05 | E41: =+I41/$I$78 -> 0.032647489 | G41: =+I41/'Unit Mix+Rents'!$D$14 -> 5928.7872 | I41: =+D41*SUM(I34:I40) -> 1660060.4
B43: Total Hard Costs | E43: =+I43/$I$78 -> 0.68559726 | G43: =SUM(G34:G42) -> 124504.53 | I43: =SUM(I34:I42) -> 34861269
B45: Market Analysis | E45: =+I45/$I$78 -> 0.00011799868 | G45: =+I45/'Unit Mix+Rents'!$D$14 -> 21.428571 | I45: 6000
B46: Architect & Engineering | E46: =+I46/$I$78 -> 0.014749834 | G46: =+I46/'Unit Mix+Rents'!$D$14 -> 2678.5714 | I46: 750000
B47: Plan Review Fees | E47: =+I47/$I$78 -> 0.00068559726 | G47: =+I47/'Unit Mix+Rents'!$D$14 -> 124.50453 | I47: =MAX(60,0.001*I43) -> 34861.269
B48: Permit, ROW and Impact Fees | E48: =+I48/$I$78 -> 0.0034291663 | G48: =+I48/'Unit Mix+Rents'!$D$14 -> 622.73694 | I48: =60+0.005*I43 -> 174366.34
B49: Environmental Study and Geotech | E49: =+I49/$I$78 -> 0.00078665784 | G49: =+I49/'Unit Mix+Rents'!$D$14 -> 142.85714 | I49: 40000
B50: Construction/Builder's Risk | E50: =+I50/$I$78 -> 0.0024583057 | G50: =+I50/'Unit Mix+Rents'!$D$14 -> 446.42857 | I50: 125000
B51: Accounting Fees | E51: =+I51/$I$78 -> 0.00078665784 | G51: =+I51/'Unit Mix+Rents'!$D$14 -> 142.85714 | I51: 40000
B52: LHC Fees | E52: =+I52/$I$78 -> 0.0040055762 | G52: =+I52/'Unit Mix+Rents'!$D$14 -> 727.41304 | I52: =4000+6000+6000+3000+500+0.1*'Tax Credit Calc'!F22 -> 203675.65
B53: Appraisal | E53: =+I53/$I$78 -> 0.00049166115 | G53: =+I53/'Unit Mix+Rents'!$D$14 -> 89.285714 | I53: 25000
B54: Title & Recording | E54: =+I54/$I$78 -> 0.0024583057 | G54: =+I54/'Unit Mix+Rents'!$D$14 -> 446.42857 | I54: 125000
B55: RE Taxes During Construction | E55: =+I55/$I$78 -> 0 | G55: =+I55/'Unit Mix+Rents'!$D$14 -> 0 | I55: 0
B56: Survey | E56: =+I56/$I$78 -> 0.00013766512 | G56: =+I56/'Unit Mix+Rents'!$D$14 -> 25 | I56: 7000
B57: Marketing/Lease-Up | E57: =+I57/$I$78 -> 0.0014749834 | G57: =+I57/'Unit Mix+Rents'!$D$14 -> 267.85714 | I57: 75000
B58: FF&E (Common Areas) | E58: =+I58/$I$78 -> 0.00078665784 | G58: =+I58/'Unit Mix+Rents'!$D$14 -> 142.85714 | I58: 40000
...

Sheet S&U Timing
A1: SOURCES AND USES TIMING
D4: TOTAL DEV COSTS | E4: Check | G4: Closings | H4: Preconstruction | M4: Construction Period | AE4: Stabilize
G5: 46229 | H5: =G5+30 -> 46259 | I5: =H5+30 -> 46289 | J5: =I5+30 -> 46319 | K5: =J5+30 -> 46349 | L5: =K5+30 -> 46379 | M5: =L5+30 -> 46409 | N5: =M5+30 -> 46439 | O5: =N5+30 -> 46469 | ... AD5: =AC5+30 -> 46919 | AE5: =AD5+360 -> 47279
G6: 1 | H6: =G6+1 -> 2 | I6: =H6+1 -> 3 | J6: =I6+1 -> 4 | K6: =J6+1 -> 5 | L6: =K6+1 -> 6 | M6: =L6+1 -> 7 | N6: =M6+1 -> 8 | O6: =N6+1 -> 9 | ... AD6: =AC6+1 -> 24 | AE6: YR1
A8: Sources of Funds
B10: Series 2026 Permanent Bonds | D10: =+SUM(G10:AD10) -> 26629504 | G10: =G50 -> 3126643.1 | H10: =H50 -> 156085.91 | I10: =I50 -> 156870.26 | J10: =J50 -> 157658.55 | K10: =K50 -> 158450.8 | L10: =L50 -> 410503.32 | M10: =+M50 -> 408677.17 | N10: =+N50 -> 702709.71 | O10: =+O50 -> 999099.39 | P10: =+P50 -> 1297858.1 | Q10: =+Q50 -> 1405126.9 | R10: =+R50 -> 1513228 | S10: =+S50 -> 1525230.2 | T10: =+T50 -> 1537292.7 | ... AD10: =+AD50 -> 1937968.8 | AE10: 0
B11: Tax Equity Bridge Loan | D11: =+SUM(G11:AE11) -> 11669369 | M11: =+$L$52*'Construction Estimates'!$C$30 -> 233387.38 | N11: =+$L$52*'Construction Estimates'!$C$31 -> 408427.92 | O11: =+$L$52*'Construction Estimates'!$C$32 -> 583468.46 | P11: =+$L$52*'Construction Estimates'!$C$33 -> 758509 | Q11: =+$L$52*'Construction Estimates'!$C$34 -> 816855.85 | R11: =+$L$52*'Construction Estimates'!$C$35 -> 875202.69 | S11: =+$L$52*'Construction Estimates'!$C$36 -> 875202.69 | T11: =+$L$52*'Construction Estimates'!$C37 -> 875202.69 | U11: =+$L$52*'Construction Estimates'!$C$38 -> 875202.69 | V11: =+$L$52*'Construction Estimates'!$C$39 -> 875202.69 | W11: =+$L$52*'Construction Estimates'!$C$40 -> 816855.85 | X11: =+$L$52*'Construction Estimates'!$C$41 -> 816855.85 | Y11: =+$L$52*'Construction Estimates'!$C$42 -> 758509 | Z11: =+$L$52*'Construction Estimates'!$C$43 -> 641815.31 | AA11: =+$L$52*'Construction Estimates'!$C$44 -> 525121.62 | AB11: =+$L$52*'Construction Estimates'!$C$45 -> 408427.92 | AC11: =+$L$52*'Construction Estimates'!$C$46 -> 291734.23 | AD11: =+$L$52*'Construction Estimates'!$C$47 -> 233387.38
B12: Bridge Loan Payback | D12: =+SUM(G12:AE12) -> -11669369 | M12: =-M16 -> 0 | N12: =-N16 -> 0 | O12: =-O16 -> 0 | P12: =-P16 -> 0 | Q12: =-Q16 -> 0 | R12: =-R16 -> 0 | S12: =-S16 -> 0 | T12: =-T16 -> 0 | ... W12: =-W16 -> 0 | Z12: =-Z16 -> -7293355.8 | AD12: =-AD16 -> 0 | AE12: =-AE16 -> -4376013.5
B14: Total Loan/Bond Par Amount | D14: =SUM(D10:D12) -> 26629504 | G14: =SUM(G10:G12) -> 3126643.1 | H14: =SUM(H10:H12) -> 156085.91 | I14: =SUM(I10:I12) -> 156870.26 | J14: =SUM(J10:J12) -> 157658.55 | K14: =SUM(K10:K12) -> 158450.8 | L14: =SUM(L10:L12) -> 410503.32 | M14: =SUM(M10:M12) -> 642064.56 | N14: =SUM(N10:N12) -> 1111137.6 | ... AE14: =SUM(AE10:AE12) -> -4376013.5
B16: Tax Equity Proceeds | D16: ='Sources & Uses'!I14 -> 14586712 | E16: =D16-SUM(G16:AE16) -> -2.7753413e-06 | G16: =0.2*$D$16 -> 2917342.3 | Z16: =0.5*$D$16 -> 7293355.8 | AD16: 0 | AE16: =+D16-SUM(G16:AD16) -> 4376013.5
B18: CDBG | D18: ='Sources & Uses'!I16 -> 7500000 | E18: =D18-SUM(G18:AE18) -> 0 | M18: =($D$18-SUM($G$18:$L$18))*'Construction Estimates'!$C30 -> 150000 | N18: =($D$18-SUM($G$18:$L$18))*'Construction Estimates'!$C31 -> 262500 | O18: =($D$18-SUM($G$18:$L$18))*'Construction Estimates'!$C32 -> 375000 | P18: =($D$18-SUM($G$18:$L$18))*'Construction Estimates'!$C33 -> 487500 | Q18: =($D$18-SUM($G$18:$L$18))*'Construction Estimates'!$C34 -> 525000 | R18: =($D$18-SUM($G$18:$L$18))*'Construction Estimates'!$C35 -> 562500 | S18: =($D$18-SUM($G$18:$L$18))*'Construction Estimates'!$C36 -> 562500 | T18: =($D$18-SUM($G$18:$L$18))*'Construction Estimates'!$C37 -> 562500 | U18: =($D$18-SUM($G$18:$L$18))*'Construction Estimates'!$C38 -> 562500 | V18: =($D$18-SUM($G$18:$L$18))*'Construction Estimates'!$C39 -> 562500 | W18: =($D$18-SUM($G$18:$L$18))*'Construction Estimates'!$C40 -> 525000 | X18: =($D$18-SUM($G$18:$L$18))*'Construction Estimates'!$C41 -> 525000 | Y18: =($D$18-SUM($G$18:$L$18))*'Construction Estimates'!$C42 -> 487500 | Z18: =($D$18-SUM($G$18:$L$18))*'Construction Estimates'!$C43 -> 412500 | AA18: =($D$18-SUM($G$18:$L$18))*'Construction Estimates'!$C44 -> 337500 | AB18: =($D$18-SUM($G$18:$L$18))*'Construction Estimates'!$C45 -> 262500 | AC18: =($D$18-SUM($G$18:$L$18))*'Construction Estimates'!$C46 -> 187500 | AD18: =($D$18-SUM($G$18:$L$18))*'Construction Estimates'!$C47 -> 150000 | AE18: 0
B19: LHC HOME | D19: ='Sources & Uses'!I17 -> 0 | E19: =D19-SUM(G19:AE19) -> 0 | M19: =($D$19-SUM($G$19:$L$19))*'Construction Estimates'!$C30 -> 0 | N19: =($D$19-SUM($G$19:$L$19))*'Construction Estimates'!$C31 -> 0 | O19: =($D$19-SUM($G$19:$L$19))*'Construction Estimates'!$C32 -> 0 | P19: =($D$19-SUM($G$19:$L$19))*'Construction Estimates'!$C33 -> 0 | Q19: =($D$19-SUM($G$19:$L$19))*'Construction Estimates'!$C34 -> 0 | R19: =($D$19-SUM($G$19:$L$19))*'Construction Estimates'!$C35 -> 0 | S19: =($D$19-SUM($G$19:$L$19))*'Construction Estimates'!$C36 -> 0 | T19: =($D$19-SUM($G$19:$L$19))*'Construction Estimates'!$C37 -> 0 | U19: =($D$19-SUM($G$19:$L$19))*'Construction Estimates'!$C38 -> 0 | V19: =($D$19-SUM($G$19:$L$19))*'Construction Estimates'!$C39 -> 0 | W19: =($D$19-SUM($G$19:$L$19))*'Construction Estimates'!$C40 -> 0 | AD19: =($D$19-SUM($G$19:$L$19))*'Construction Estimates'!$C41 -> 0 | AE19: 0
B21: Total Soft Money | D21: =SUM(D18:D19) -> 7500000 | E21: =D21-SUM(G21:AE21) -> 0 | G21: =SUM(G18:G19) -> 0 | H21: =SUM(H18:H19) -> 0 | I21: =SUM(I18:I19) -> 0 | J21: =SUM(J18:J19) -> 0 | K21: =SUM(K18:K19) -> 0 | L21: =SUM(L18:L19) -> 0 | M21: =SUM(M18:M19) -> 150000 | N21: =SUM(N18:N19) -> 262500 | ... AE21: =SUM(AE18:AE19) -> 0
B23: Deferred GC Fee | D23: 0 | E23: =D23-SUM(G23:AE23) -> 0
B24: Deferred Developer Fee | D24: =+'Sources & Uses'!I22 -> 2131813.1 | E24: =D24-SUM(G24:AE24) -> -4.6566129e-09 | G24: 0 | H24: 0 | I24: 0 | J24: 0 | K24: 0 | L24: 0 | M24: =+$D$24*'Construction Estimates'!$C$30 -> 42636.262 | N24: =+$D$24*'Construction Estimates'!$C$31 -> 74613.458 | O24: =+$D$24*'Construction Estimates'!$C$32 -> 106590.65 | P24: =+$D$24*'Construction Estimates'!$C$33 -> 138567.85 | Q24: =+$D$24*'Construction Estimates'!$C$34 -> 149226.92 | R24: =+$D$24*'Construction Estimates'!$C$35 -> 159885.98 | S24: =+$D$24*'Construction Estimates'!$C$36 -> 159885.98 | T24: =+$D$24*'Construction Estimates'!$C$37 -> 159885.98 | U24: =+$D$24*'Construction Estimates'!$C$38 -> 159885.98 | V24: =+$D$24*'Construction Estimates'!$C$39 -> 159885.98 | W24: =+$D$24*'Construction Estimates'!$C$40 -> 149226.92 | X24: =+$D$24*'Construction Estimates'!$C$41 -> 149226.92 | Y24: =+$D$24*'Construction Estimates'!$C$42 -> 138567.85 | Z24: =+$D$24*'Construction Estimates'!$C$43 -> 117249.72 | AA24: =+$D$24*'Construction Estimates'!$C$44 -> 95931.588 | AB24: =+$D$24*'Construction Estimates'!$C$45 -> 74613.458 | AC24: =+$D$24*'Construction Estimates'!$C$46 -> 53295.327 | AD24: =+$D$24*'Construction Estimates'!$C$47 -> 42636.262
E25: =D25-SUM(G25:AE25) -> 0
B26: Total Deferred Fees | D26: =D23+D24 -> 2131813.1 | G26: =G23+G24 -> 0 | H26: =H23+H24 -> 0 | I26: =I23+I24 -> 0 | J26: =J23+J24 -> 0 | K26: =K23+K24 -> 0 | L26: =L23+L24 -> 0 | M26: =M23+M24 -> 42636.262 | N26: =N23+N24 -> 74613.458 | ... AE26: =AE23+AE24 -> 0
A28: Total Sources of Funds | D28: =D14+D16+D21+D26 -> 50848028 | E28: =D28-SUM(G28:AE28) -> -2.7865171e-06 | G28: =G14+G16+G21+G26 -> 6043985.4 | H28: =H14+H16+H21+H26 -> 156085.91 | I28: =I14+I16+I21+I26 -> 156870.26 | J28: =J14+J16+J21+J26 -> 157658.55 | K28: =K14+K16+K21+K26 -> 158450.8 | L28: =L14+L16+L21+L26 -> 410503.32 | M28: =M14+M16+M21+M26 -> 834700.82 | N28: =N14+N16+N21+N26 -> 1448251.1 | ... AE28: =AE14+AE16+AE21+AE26 -> -8.3260238e-07
A30: Uses of Funds
B32: Land/Building Acquisition Cost | D32: ='Sources & Uses'!I30 -> 4000000 | E32: =D32-SUM(G32:AE32) -> 0 | G32: =D32 -> 4000000
B33: Total Hard Costs | D33: ='Sources & Uses'!I43 -> 34861269 | E33: =D33-SUM(G33:AE33) -> 0 | L33: 250000 | M33: =($D$33-$L$33)*'Construction Estimates'!$C30 -> 692225.38 | N33: =($D$33-$L$33)*'Construction Estimates'!$C31 -> 1211394.4 | O33: =($D$33-$L$33)*'Construction Estimates'!$C32 -> 1730563.4 | P33: =($D$33-$L$33)*'Construction Estimates'!$C33 -> 2249732.5 | Q33: =($D$33-$L$33)*'Construction Estimates'!$C34 -> 2422788.8 | R33: =($D$33-$L$33)*'Construction Estimates'!$C35 -> 2595845.2 | S33: =($D$33-$L$33)*'Construction Estimates'!$C36 -> 2595845.2 | T33: =($D$33-$L$33)*'Construction Estimates'!$C37 -> 2595845.2 | U33: =($D$33-$L$33)*'Construction Estimates'!$C38 -> 2595845.2 | V33: =($D$33-$L$33)*'Construction Estimates'!$C39 -> 2595845.2 | W33: =($D$33-$L$33)*'Construction Estimates'!$C40 -> 2422788.8 | X33: =($D$33-$L$33)*'Construction Estimates'!$C41 -> 2422788.8 | Y33: =($D$33-$L$33)*'Construction Estimates'!$C42 -> 2249732.5 | Z33: =($D$33-$L$33)*'Construction Estimates'!$C43 -> 1903619.8 | AA33: =($D$33-$L$33)*'Construction Estimates'!$C44 -> 1557507.1 | AB33: =($D$33-$L$33)*'Construction Estimates'!$C45 -> 1211394.4 | AC33: =($D$33-$L$33)*'Construction Estimates'!$C46 -> 865281.72 | AD33: =($D$33-$L$33)*'Construction Estimates'!$C47 -> 692225.38 | AE33: 0
B34: Total Soft Costs | D34: ='Sources & Uses'!I61 -> 1745903.3 | E34: =D34-SUM(G34:AE34) -> -3.4458935e-08 | G34: =D34*0.6 -> 1047542 | H34: =(D34-G34)/5 -> 139672.26 | I34: =H34 -> 139672.26 | J34: =I34 -> 139672.26 | K34: =J34 -> 139672.26 | L34: =K34 -> 139672.26
B35: Developer Fee | D35: =+'Sources & Uses'!I65 -> 5921703 | E35: =D35-SUM(G35:AE35) -> 6.2491745e-07 | M35: =$D$35*'Construction Estimates'!$C30 -> 118434.06 | N35: =$D$35*'Construction Estimates'!$C31 -> 207259.6 | O35: =$D$35*'Construction Estimates'!$C32 -> 296085.15 | P35: =$D$35*'Construction Estimates'!$C33 -> 384910.69 | Q35: =$D$35*'Construction Estimates'!$C34 -> 414519.21 | R35: =$D$35*'Construction Estimates'!$C35 -> 444127.72 | S35: =$D$35*'Construction Estimates'!$C36 -> 444127.72 | T35: =$D$35*'Construction Estimates'!$C37 -> 444127.72 | U35: =$D$35*'Construction Estimates'!$C38 -> 444127.72 | V35: =$D$35*'Construction Estimates'!$C39 -> 444127.72 | W35: =$D$35*'Construction Estimates'!$C40 -> 414519.21 | X35: =$D$35*'Construction Estimates'!$C41 -> 414519.21 | Y35: =$D$35*'Construction Estimates'!$C42 -> 384910.69 | Z35: =$D$35*'Construction Estimates'!$C43 -> 325693.66 | AA35: =$D$35*'Construction Estimates'!$C44 -> 266476.63 | AB35: =$D$35*'Construction Estimates'!$C45 -> 207259.6 | AC35: =$D$35*'Construction Estimates'!$C46 -> 148042.57 | AD35: =$D$35*'Construction Estimates'!$C47 -> 118434.06 | AE35: 0
B37: Total Construction Cost | D37: =+SUM(D32:D35) -> 46528875 | E37: =D37-SUM(G37:AE37) -> 5.8859587e-07 | G37: =+SUM(G32:G35) -> 5047542 | H37: =+SUM(H32:H35) -> 139672.26 | I37: =+SUM(I32:I35) -> 139672.26 | J37: =+SUM(J32:J35) -> 139672.26 | K37: =+SUM(K32:K35) -> 139672.26 | L37: =+SUM(L32:L35) -> 389672.26 | M37: =+SUM(M32:M35) -> 810659.44 | N37: =+SUM(N32:N35) -> 1418654 | ... AE37: =+SUM(AE32:AE35) -> 0
B39: Total Reserves | D39: ='Sources & Uses'!I72 -> 1398305.4 | E39: =D39-SUM(G39:AD39) -> -9.3830749e-08 | AD39: =+D39 -> 1398305.4 | AE39: =-AE41-AE42 -> -1860331
B41: Capitalized Construction Interest | D41: =+SUM(G41:AD41) -> 1507979.2 | G41: =+'Loan Amortization'!C11 -> 15633.215 | H41: =+'Loan Amortization'!D11 -> 16413.645 | I41: =+'Loan Amortization'!E11 -> 17197.996 | J41: =+'Loan Amortization'!F11 -> 17986.289 | K41: =+'Loan Amortization'!G11 -> 18778.543 | L41: =+'Loan Amortization'!H11 -> 20831.06 | M41: =+'Loan Amortization'!I11 -> 22874.446 | N41: =+'Loan Amortization'!J11 -> 26387.994 | ... AE41: =+'Loan Amortization'!AA11 -> 1597770.2
B42: Capitalized Bridge Interest | D42: =+SUM(G42:AD42) -> 432058.4 | G42: =+'Loan Amortization'!C23 -> 0 | H42: =+'Loan Amortization'!D23 -> 0 | I42: =+'Loan Amortization'!E23 -> 0 | J42: =+'Loan Amortization'!F23 -> 0 | K42: =+'Loan Amortization'!G23 -> 0 | L42: =+'Loan Amortization'!H23 -> 0 | M42: =+'Loan Amortization'!I23 -> 1166.9369 | N42: =+'Loan Amortization'!J23 -> 3209.0765 | ... AE42: =+'Loan Amortization'!AA23 -> 262560.81
B44: Total Construction Cost | D44: =+SUM(D41:D42) -> 1940037.6 | E44: =D44-SUM(G44:AD44) -> 0 | G44: =+SUM(G41:G42) -> 15633.215 | H44: =+SUM(H41:H42) -> 16413.645 | I44: =+SUM(I41:I42) -> 17197.996 | J44: =+SUM(J41:J42) -> 17986.289 | K44: =+SUM(K41:K42) -> 18778.543 | L44: =+SUM(L41:L42) -> 20831.06 | M44: =+SUM(M41:M42) -> 24041.382 | N44: =+SUM(N41:N42) -> 29597.071 | ... AE44: =+SUM(AE41:AE42) -> 1860331
B46: Total Other Costs | D46: =+'Financing Assumptions'!D53 -> 980810.23 | E46: =D46-SUM(G46:AE46) -> -2.4447218e-09 | G46: =+D46 -> 980810.23 | H46: 0 | I46: 0 | J46: 0 | K46: 0 | L46: 0 | M46: 0 | N46: 0 | O46: 0 | P46: 0 | Q46: 0 | R46: 0 | S46: 0 | T46: 0 | U46: 0 | V46: 0 | W46: 0 | X46: 0 | Y46: 0 | Z46: 0 | AA46: 0 | AB46: 0 | AC46: 0 | AD46: 0 | AE46: 0
A48: Total Uses of Funds | D48: =+SUM(D37,D39,D44,D46) -> 50848028 | E48: =D48-SUM(G48:AD48) -> 5.0663948e-07 | G48: =+SUM(G37,G39,G44,G46) -> 6043985.4 | H48: =+SUM(H37,H39,H44,H46) -> 156085.91 | I48: =+SUM(I37,I39,I44,I46) -> 156870.26 | J48: =+SUM(J37,J39,J44,J46) -> 157658.55 | K48: =+SUM(K37,K39,K44,K46) -> 158450.8 | L48: =+SUM(L37,L39,L44,L46) -> 410503.32 | M48: =+SUM(M37,M39,M44,M46) -> 834700.82 | N48: =+SUM(N37,N39,N44,N46) -> 1448251.1 | ... AE48: =+SUM(AE37,AE39,AE44,AE46) -> 3.0729687e-05
B49: Check | D49: =D28-D48 -> -1.0751188e-05 | G49: =G28-G48 -> -5.2992254e-07 | H49: =H28-H48 -> 6.1409082e-09 | I49: =I28-I48 -> 6.6647772e-09 | J49: =J28-J48 -> 2.1245796e-09 | K49: =K28-K48 -> -7.21775e-09 | L49: =L28-L48 -> -1.6530976e-08 | M49: =M28-M48 -> -7.7998266e-08 | N49: =N28-N48 -> -1.0500662e-07 | ... AE49: =AE28-AE48 -> -3.1562289e-05
B50: Bonds Fund Needed | G50: =+G48-SUM(G11,G12,G16,G18,G19,G23,G24) -> 3126643.1 | H50: =+H48-SUM(H11,H12,H16,H18,H19,H23,H24) -> 156085.91 | I50: =+I48-SUM(I11,I12,I16,I18,I19,I23,I24) -> 156870.26 | J50: =+J48-SUM(J11,J12,J16,J18,J19,J23,J24) -> 157658.55 | K50: =+K48-SUM(K11,K12,K16,K18,K19,K23,K24) -> 158450.8 | L50: =+L48-SUM(L11,L12,L16,L18,L19,L23,L24) -> 410503.32 | M50: =+M48-SUM(M11,M12,M16,M18,M19,M23,M24) -> 408677.17 | N50: =+N48-SUM(N11,N12,N16,N18,N19,N23,N24) -> 702709.71 | ... AE50: =+AE48-SUM(AE11,AE12,AE16,AE18,AE19,AE23,AE24) -> 3.1562289e-05
B51: Bonds O/S Balance | G51: =+G50 -> 3126643.1 | H51: =+G51+H50 -> 3282729 | I51: =+H51+I50 -> 3439599.3 | J51: =+I51+J50 -> 3597257.8 | K51: =+J51+K50 -> 3755708.6 | L51: =+K51+L50 -> 4166211.9 | M51: =+L51+M50 -> 4574889.1 | N51: =+M51+N50 -> 5277598.8 | O51: =+N51+O50 -> 6276698.2 | ... AE51: =+AD51+AE50 -> 26629504
B52: Tax Equity O/S Balance | G52: =+D16-G11-G16 -> 11669369 | H52: =+G52-H11-H16 -> 11669369 | I52: =+H52-I11-I16 -> 11669369 | J52: =+I52-J11-J16 -> 11669369 | K52: =+J52-K11-K16 -> 11669369 | L52: =+K52-L11-L16 -> 11669369 | M52: =+L52-M11-M16 -> 11435982 | N52: =+M52-N11-N16 -> 11027554 | O52: =+N52-O11-O16 -> 10444085 | ... AE52: =+AD52-AE11-AE16 -> -11669369

Sheet NOI Calc
A1: NET OPERATING INCOME CALCULATION
H3: Per Unit | I3: Monthly | J3: Annual | K3: PUPA
A4: Gross Revenues:
A5: Gross Rental Income | H5: =+I5/'Unit Mix+Rents'!$D$14 -> 1038.0714 | I5: =+J5/12 -> 290660 | J5: ='Unit Mix+Rents'!J14*12 -> 3487920 | K5: =+J5/'Unit Mix+Rents'!$D$14 -> 12456.857
A6: Tenant Charges | H6: 5 | I6: =+J6/12 -> 1400 | J6: =+H6*'Unit Mix+Rents'!$D$14*12 -> 16800 | K6: =+J6/'Unit Mix+Rents'!$D$14 -> 60
A7: Pet Fees | H7: 5 | I7: =+J7/12 -> 1400 | J7: =+H7*'Unit Mix+Rents'!$D$14*12 -> 16800 | K7: =+J7/'Unit Mix+Rents'!$D$14 -> 60
A9: Gross Revenues | H9: =+SUM(H5:H7) -> 1048.0714 | I9: =+SUM(I5:I7) -> 293460 | J9: =+SUM(J5:J7) -> 3521520 | K9: =+SUM(K5:K7) -> 12576.857
A11: Vacancy Adjustment | D11: 0.07 | H11: =+I11/'Unit Mix+Rents'!$D$14 -> -73.365 | I11: =+J11/12 -> -20542.2 | J11: =+J9*-D11 -> -246506.4 | K11: =+J11/'Unit Mix+Rents'!$D$14 -> -880.38
A13: Net Revenues | H13: =+H9+H11 -> 974.70643 | I13: =+I9+I11 -> 272917.8 | J13: =+J9+J11 -> 3275013.6 | K13: =+K9+K11 -> 11696.477
A15: Operating Expenses
A16: Management Fee | D16: 0.035 | H16: =+I16/'Unit Mix+Rents'!$D$14 -> 34.114725 | I16: =+J16/12 -> 9552.123 | J16: =+J13*D16 -> 114625.48 | K16: =+J16/'Unit Mix+Rents'!$D$14 -> 409.3767
A17: Staff Payroll | H17: =+I17/'Unit Mix+Rents'!$D$14 -> 55.838095 | I17: =+J17/12 -> 15634.667 | J17: =+'Expense Detail'!F13 -> 187616 | K17: =+J17/'Unit Mix+Rents'!$D$14 -> 670.05714
A18: Maintenance + Make Ready | H18: =+I18/'Unit Mix+Rents'!$D$14 -> 63.333333 | I18: =+J18/12 -> 17733.333 | J18: =+'Expense Detail'!F20 -> 212800 | K18: =+J18/'Unit Mix+Rents'!$D$14 -> 760
A19: Utilities | H19: =+I19/'Unit Mix+Rents'!$D$14 -> 62.535714 | I19: =+J19/12 -> 17510 | J19: =+'Expense Detail'!F39 -> 210120 | K19: =+J19/'Unit Mix+Rents'!$D$14 -> 750.42857
A20: Contract Services | H20: =+I20/'Unit Mix+Rents'!$D$14 -> 17.857143 | I20: =+J20/12 -> 5000 | J20: =+'Expense Detail'!F50 -> 60000 | K20: =+J20/'Unit Mix+Rents'!$D$14 -> 214.28571
A21: Compliance | H21: 45 | I21: =+J21/12 -> 1050 | J21: =+H21*'Unit Mix+Rents'!$D$14 -> 12600 | K21: =+J21/'Unit Mix+Rents'!$D$14 -> 45
A22: Admin Expenses | H22: 100 | I22: =+J22/12 -> 2333.3333 | J22: =+H22*'Unit Mix+Rents'!$D$14 -> 28000 | K22: =+J22/'Unit Mix+Rents'!$D$14 -> 100
A23: Property Insurance | H23: =+I23/'Unit Mix+Rents'!$D$14 -> 125 | I23: =+J23/12 -> 35000 | J23: =+'Expense Detail'!F65 -> 420000 | K23: =+J23/'Unit Mix+Rents'!$D$14 -> 1500
A24: Property Taxes | H24: =+I24/'Unit Mix+Rents'!$D$14 -> 14.880952 | I24: =+J24/12 -> 4166.6667 | J24: =+'Expense Detail'!F60 -> 50000 | K24: =+J24/'Unit Mix+Rents'!$D$14 -> 178.57143
A26: Total Operating Expenses | H26: =+SUM(H16:H25) -> 518.55996 | I26: =+SUM(I16:I25) -> 107980.12 | J26: =+SUM(J16:J25) -> 1295761.5 | K26: =+SUM(K16:K25) -> 4627.7196
A27: Expenses as a % of Gross Revenues | K27: =+K26/K9 -> 0.36795517
A29: NET OPERATING INCOME | H29: =+H13-H26 -> 456.14647 | I29: =+I13-I26 -> 164937.68 | J29: =+J13-J26 -> 1979252.1 | K29: =+K13-K26 -> 7068.7576
A30: NOI as a % of Gross Revenues | K30: =+K29/K9 -> 0.56204483
A33: Replacement Reserves | H33: =+I33/'Unit Mix+Rents'!$D$14 -> 41.666667 | I33: =+J33/12 -> 11666.667 | J33: =+K33*'Unit Mix+Rents'!$D$14 -> 140000 | K33: 500
A34: Issuer Fee | H34: =+I34/'Unit Mix+Rents'!$D$14 -> 15.850895 | I34: =+J34/12 -> 4438.2506 | J34: =+'17-year Pro Forma'!D35 -> 53259.007 | K34: =+J34/'Unit Mix+Rents'!$D$14 -> 190.21074
A35: Trustee Fee | H35: =+I35/'Unit Mix+Rents'!$D$14 -> 1.4880952 | I35: =+J35/12 -> 416.66667 | J35: =+'17-year Pro Forma'!D36 -> 5000 | K35: =+J35/'Unit Mix+Rents'!$D$14 -> 17.857143
A36: Servicing Fee | H36: =+I36/'Unit Mix+Rents'!$D$14 -> 7.9254475 | I36: =+J36/12 -> 2219.1253 | J36: =+'17-year Pro Forma'!D37 -> 26629.504 | K36: =+J36/'Unit Mix+Rents'!$D$14 -> 95.10537
A38: Operating Cash Flow | H38: =+H29-SUM(H34:H36) -> 430.88203 | I38: =+I29-SUM(I34:I36) -> 157863.63 | J38: =+J29-SUM(J34:J36) -> 1894363.6 | K38: =+K29-SUM(K34:K36) -> 6765.5843
A39: Operating Cash Flow as a % of Gross Revenues | J39: =+J38/J13 -> 0.57842924 | K39: =+K38/K13 -> 0.57842924

Sheet Lease-Up Period
A1: YEAR 1 LEASE-UP — MONTHLY CASH FLOW
D4: Month 1 | E4: Month 2 | F4: Month 3 | G4: Month 4 | H4: Month 5 | I4: Month 6 | J4: Month 7 | K4: Month 8 | L4: Month 9 | M4: Month 10 | N4: Month 11 | O4: Month 12 | P4: Total
A6: Gross Rental Income | D6: =+'NOI Calc'!$J$5/12 -> 290660 | E6: =+'NOI Calc'!$J$5/12 -> 290660 | F6: =+'NOI Calc'!$J$5/12 -> 290660 | G6: =+'NOI Calc'!$J$5/12 -> 290660 | H6: =+'NOI Calc'!$J$5/12 -> 290660 | I6: =+'NOI Calc'!$J$5/12 -> 290660 | J6: =+'NOI Calc'!$J$5/12 -> 290660 | K6: =+'NOI Calc'!$J$5/12 -> 290660 | ... O6: =+'NOI Calc'!$J$5/12 -> 290660 | P6: =SUM(D6:O6) -> 3487920
A7: Other Income | D7: =(+'NOI Calc'!$J$6+'NOI Calc'!$J$7)/12 -> 2800 | E7: =(+'NOI Calc'!$J$6+'NOI Calc'!$J$7)/12 -> 2800 | F7: =(+'NOI Calc'!$J$6+'NOI Calc'!$J$7)/12 -> 2800 | G7: =(+'NOI Calc'!$J$6+'NOI Calc'!$J$7)/12 -> 2800 | H7: =(+'NOI Calc'!$J$6+'NOI Calc'!$J$7)/12 -> 2800 | I7: =(+'NOI Calc'!$J$6+'NOI Calc'!$J$7)/12 -> 2800 | J7: =(+'NOI Calc'!$J$6+'NOI Calc'!$J$7)/12 -> 2800 | K7: =(+'NOI Calc'!$J$6+'NOI Calc'!$J$7)/12 -> 2800 | ... O7: =(+'NOI Calc'!$J$6+'NOI Calc'!$J$7)/12 -> 2800 | P7: =SUM(D7:O7) -> 33600
A9: Gross Revenue | D9: =+SUM(D6:D7) -> 293460 | E9: =+SUM(E6:E7) -> 293460 | F9: =+SUM(F6:F7) -> 293460 | G9: =+SUM(G6:G7) -> 293460 | H9: =+SUM(H6:H7) -> 293460 | I9: =+SUM(I6:I7) -> 293460 | J9: =+SUM(J6:J7) -> 293460 | K9: =+SUM(K6:K7) -> 293460 | ... O9: =+SUM(O6:O7) -> 293460 | P9: =SUM(D9:O9) -> 3521520
A10: Vacancy Adjustment | D10: =-MAX('NOI Calc'!$D$11,1-D$55)*D9 -> -262017.86 | E10: =-MAX('NOI Calc'!$D$11,1-E$55)*E9 -> -230575.71 | F10: =-MAX('NOI Calc'!$D$11,1-F$55)*F9 -> -199133.57 | G10: =-MAX('NOI Calc'!$D$11,1-G$55)*G9 -> -167691.43 | H10: =-MAX('NOI Calc'!$D$11,1-H$55)*H9 -> -136249.29 | I10: =-MAX('NOI Calc'!$D$11,1-I$55)*I9 -> -104807.14 | J10: =-MAX('NOI Calc'!$D$11,1-J$55)*J9 -> -73365 | K10: =-MAX('NOI Calc'!$D$11,1-K$55)*K9 -> -41922.857 | ... O10: =-MAX('NOI Calc'!$D$11,1-O$55)*O9 -> -20542.2 | P10: =SUM(D10:O10) -> -1297931.7
A12: Net Revenue | D12: =+D9+D10 -> 31442.143 | E12: =+E9+E10 -> 62884.286 | F12: =+F9+F10 -> 94326.429 | G12: =+G9+G10 -> 125768.57 | H12: =+H9+H10 -> 157210.71 | I12: =+I9+I10 -> 188652.86 | J12: =+J9+J10 -> 220095 | K12: =+K9+K10 -> 251537.14 | ... O12: =+O9+O10 -> 272917.8 | P12: =SUM(D12:O12) -> 2223588.3
A14: Operating Expenses | C14: Fixed %
B16: Management Fee | D16: =+D12*'NOI Calc'!$D$16 -> 1100.475 | E16: =+E12*'NOI Calc'!$D$16 -> 2200.95 | F16: =+F12*'NOI Calc'!$D$16 -> 3301.425 | G16: =+G12*'NOI Calc'!$D$16 -> 4401.9 | H16: =+H12*'NOI Calc'!$D$16 -> 5502.375 | I16: =+I12*'NOI Calc'!$D$16 -> 6602.85 | J16: =+J12*'NOI Calc'!$D$16 -> 7703.325 | K16: =+K12*'NOI Calc'!$D$16 -> 8803.8 | ... O16: =+O12*'NOI Calc'!$D$16 -> 9552.123 | P16: =SUM(D16:O16) -> 77825.592
B17: Payroll | C17: 1 | D17: =('NOI Calc'!$J$17/12)*($C17+(1-$C17)*D$55) -> 15634.667 | E17: =('NOI Calc'!$J$17/12)*($C17+(1-$C17)*E$55) -> 15634.667 | F17: =('NOI Calc'!$J$17/12)*($C17+(1-$C17)*F$55) -> 15634.667 | G17: =('NOI Calc'!$J$17/12)*($C17+(1-$C17)*G$55) -> 15634.667 | H17: =('NOI Calc'!$J$17/12)*($C17+(1-$C17)*H$55) -> 15634.667 | I17: =('NOI Calc'!$J$17/12)*($C17+(1-$C17)*I$55) -> 15634.667 | J17: =('NOI Calc'!$J$17/12)*($C17+(1-$C17)*J$55) -> 15634.667 | K17: =('NOI Calc'!$J$17/12)*($C17+(1-$C17)*K$55) -> 15634.667 | ... O17: =('NOI Calc'!$J$17/12)*($C17+(1-$C17)*O$55) -> 15634.667 | P17: =SUM(D17:O17) -> 187616
B18: Maintenance | C18: 0 | D18: =('NOI Calc'!$J$18/12)*($C18+(1-$C18)*D$55) -> 1900 | E18: =('NOI Calc'!$J$18/12)*($C18+(1-$C18)*E$55) -> 3800 | F18: =('NOI Calc'!$J$18/12)*($C18+(1-$C18)*F$55) -> 5700 | G18: =('NOI Calc'!$J$18/12)*($C18+(1-$C18)*G$55) -> 7600 | H18: =('NOI Calc'!$J$18/12)*($C18+(1-$C18)*H$55) -> 9500 | I18: =('NOI Calc'!$J$18/12)*($C18+(1-$C18)*I$55) -> 11400 | J18: =('NOI Calc'!$J$18/12)*($C18+(1-$C18)*J$55) -> 13300 | K18: =('NOI Calc'!$J$18/12)*($C18+(1-$C18)*K$55) -> 15200 | ... O18: =('NOI Calc'!$J$18/12)*($C18+(1-$C18)*O$55) -> 17733.333 | P18: =SUM(D18:O18) -> 138700
B19: Utilities | C19: 0.75 | D19: =('NOI Calc'!$J$19/12)*($C19+(1-$C19)*D$55) -> 13601.518 | E19: =('NOI Calc'!$J$19/12)*($C19+(1-$C19)*E$55) -> 14070.536 | F19: =('NOI Calc'!$J$19/12)*($C19+(1-$C19)*F$55) -> 14539.554 | G19: =('NOI Calc'!$J$19/12)*($C19+(1-$C19)*G$55) -> 15008.571 | H19: =('NOI Calc'!$J$19/12)*($C19+(1-$C19)*H$55) -> 15477.589 | I19: =('NOI Calc'!$J$19/12)*($C19+(1-$C19)*I$55) -> 15946.607 | J19: =('NOI Calc'!$J$19/12)*($C19+(1-$C19)*J$55) -> 16415.625 | K19: =('NOI Calc'!$J$19/12)*($C19+(1-$C19)*K$55) -> 16884.643 | ... O19: =('NOI Calc'!$J$19/12)*($C19+(1-$C19)*O$55) -> 17510 | P19: =SUM(D19:O19) -> 191828.3
B20: Administrative | C20: 1 | D20: =(('NOI Calc'!$J$20+'NOI Calc'!$J$21+'NOI Calc'!$J$22)/12)*($C20+(1-$C20)*D$55) -> 8383.3333 | E20: =(('NOI Calc'!$J$20+'NOI Calc'!$J$21+'NOI Calc'!$J$22)/12)*($C20+(1-$C20)*E$55) -> 8383.3333 | F20: =(('NOI Calc'!$J$20+'NOI Calc'!$J$21+'NOI Calc'!$J$22)/12)*($C20+(1-$C20)*F$55) -> 8383.3333 | G20: =(('NOI Calc'!$J$20+'NOI Calc'!$J$21+'NOI Calc'!$J$22)/12)*($C20+(1-$C20)*G$55) -> 8383.3333 | H20: =(('NOI Calc'!$J$20+'NOI Calc'!$J$21+'NOI Calc'!$J$22)/12)*($C20+(1-$C20)*H$55) -> 8383.3333 | I20: =(('NOI Calc'!$J$20+'NOI Calc'!$J$21+'NOI Calc'!$J$22)/12)*($C20+(1-$C20)*I$55) -> 8383.3333 | J20: =(('NOI Calc'!$J$20+'NOI Calc'!$J$21+'NOI Calc'!$J$22)/12)*($C20+(1-$C20)*J$55) -> 8383.3333 | K20: =(('NOI Calc'!$J$20+'NOI Calc'!$J$21+'NOI Calc'!$J$22)/12)*($C20+(1-$C20)*K$55) -> 8383.3333 | ... O20: =(('NOI Calc'!$J$20+'NOI Calc'!$J$21+'NOI Calc'!$J$22)/12)*($C20+(1-$C20)*O$55) -> 8383.3333 | P20: =SUM(D20:O20) -> 100600
B21: Property Insurance | C21: 1 | D21: =('NOI Calc'!$J$23/12)*($C21+(1-$C21)*D$55) -> 35000 | E21: =('NOI Calc'!$J$23/12)*($C21+(1-$C21)*E$55) -> 35000 | F21: =('NOI Calc'!$J$23/12)*($C21+(1-$C21)*F$55) -> 35000 | G21: =('NOI Calc'!$J$23/12)*($C21+(1-$C21)*G$55) -> 35000 | H21: =('NOI Calc'!$J$23/12)*($C21+(1-$C21)*H$55) -> 35000 | I21: =('NOI Calc'!$J$23/12)*($C21+(1-$C21)*I$55) -> 35000 | J21: =('NOI Calc'!$J$23/12)*($C21+(1-$C21)*J$55) -> 35000 | K21: =('NOI Calc'!$J$23/12)*($C21+(1-$C21)*K$55) -> 35000 | ... O21: =('NOI Calc'!$J$23/12)*($C21+(1-$C21)*O$55) -> 35000 | P21: =SUM(D21:O21) -> 420000
B22: Property Taxes | D22: =+'Expense Detail'!$F$60/12 -> 4166.6667 | E22: =+'Expense Detail'!$F$60/12 -> 4166.6667 | F22: =+'Expense Detail'!$F$60/12 -> 4166.6667 | G22: =+'Expense Detail'!$F$60/12 -> 4166.6667 | H22: =+'Expense Detail'!$F$60/12 -> 4166.6667 | I22: =+'Expense Detail'!$F$60/12 -> 4166.6667 | J22: =+'Expense Detail'!$F$60/12 -> 4166.6667 | K22: =+'Expense Detail'!$F$60/12 -> 4166.6667 | ... O22: =+'Expense Detail'!$F$60/12 -> 4166.6667 | P22: =SUM(D22:O22) -> 50000
A24: Total Operating Expenses | D24: =+SUM(D16:D23) -> 79786.66 | E24: =+SUM(E16:E23) -> 83256.152 | F24: =+SUM(F16:F23) -> 86725.645 | G24: =+SUM(G16:G23) -> 90195.138 | H24: =+SUM(H16:H23) -> 93664.631 | I24: =+SUM(I16:I23) -> 97134.124 | J24: =+SUM(J16:J23) -> 100603.62 | K24: =+SUM(K16:K23) -> 104073.11 | ... O24: =+SUM(O16:O23) -> 107980.12 | P24: =SUM(D24:O24) -> 1166569.9
A26: NET OPERATING INCOME | D26: =+D12-D24 -> -48344.517 | E26: =+E12-E24 -> -20371.867 | F26: =+F12-F24 -> 7600.7833 | G26: =+G12-G24 -> 35573.433 | H26: =+H12-H24 -> 63546.083 | I26: =+I12-I24 -> 91518.733 | J26: =+J12-J24 -> 119491.38 | K26: =+K12-K24 -> 147464.03 | ... O26: =+O12-O24 -> 164937.68 | P26: =SUM(D26:O26) -> 1057018.4
A28: Replacement Reserves | D28: =+'NOI Calc'!$J$33/12 -> 11666.667 | E28: =+'NOI Calc'!$J$33/12 -> 11666.667 | F28: =+'NOI Calc'!$J$33/12 -> 11666.667 | G28: =+'NOI Calc'!$J$33/12 -> 11666.667 | H28: =+'NOI Calc'!$J$33/12 -> 11666.667 | I28: =+'NOI Calc'!$J$33/12 -> 11666.667 | J28: =+'NOI Calc'!$J$33/12 -> 11666.667 | K28: =+'NOI Calc'!$J$33/12 -> 11666.667 | ... O28: =+'NOI Calc'!$J$33/12 -> 11666.667 | P28: =SUM(D28:O28) -> 140000
A30: Senior A Bond Interest | D30: =+'Loan Amortization'!$C$28*'Financing Assumptions'!$C$28/12 -> 122051.89 | E30: =+'Loan Amortization'!$C$28*'Financing Assumptions'!$C$28/12 -> 122051.89 | F30: =+'Loan Amortization'!$C$28*'Financing Assumptions'!$C$28/12 -> 122051.89 | G30: =+'Loan Amortization'!$C$28*'Financing Assumptions'!$C$28/12 -> 122051.89 | H30: =+'Loan Amortization'!$C$28*'Financing Assumptions'!$C$28/12 -> 122051.89 | I30: =+'Loan Amortization'!$C$28*'Financing Assumptions'!$C$28/12 -> 122051.89 | J30: =+'Loan Amortization'!$C$28*'Financing Assumptions'!$C$28/12 -> 122051.89 | K30: =+'Loan Amortization'!$C$28*'Financing Assumptions'!$C$28/12 -> 122051.89 | ... O30: =+'Loan Amortization'!$C$28*'Financing Assumptions'!$C$28/12 -> 122051.89 | P30: =SUM(D30:O30) -> 1464622.7
A31: Senior A Bond Principal | D31: 0 | E31: 0 | F31: 0 | G31: 0 | H31: 0 | I31: 0 | J31: 0 | K31: 0 | L31: 0 | M31: 0 | N31: 0 | O31: 0 | P31: =SUM(D31:O31) -> 0
A33: Cash Available after Bond Pmts | D33: =+D26-D28-D30-D31 -> -182063.08 | E33: =+E26-E28-E30-E31 -> -154090.43 | F33: =+F26-F28-F30-F31 -> -126117.78 | G33: =+G26-G28-G30-G31 -> -98145.125 | H33: =+H26-H28-H30-H31 -> -70172.475 | I33: =+I26-I28-I30-I31 -> -42199.825 | J33: =+J26-J28-J30-J31 -> -14227.175 | K33: =+K26-K28-K30-K31 -> 13745.475 | ... O33: =+O26-O28-O30-O31 -> 31219.118 | P33: =SUM(D33:O33) -> -547604.26
A36: Issuer Fee | D36: =+'Loan Amortization'!$C$28*'Financing Assumptions'!$C$30/12 -> 4438.2506 | E36: =+'Loan Amortization'!$C$28*'Financing Assumptions'!$C$30/12 -> 4438.2506 | F36: =+'Loan Amortization'!$C$28*'Financing Assumptions'!$C$30/12 -> 4438.2506 | G36: =+'Loan Amortization'!$C$28*'Financing Assumptions'!$C$30/12 -> 4438.2506 | H36: =+'Loan Amortization'!$C$28*'Financing Assumptions'!$C$30/12 -> 4438.2506 | I36: =+'Loan Amortization'!$C$28*'Financing Assumptions'!$C$30/12 -> 4438.2506 | J36: =+'Loan Amortization'!$C$28*'Financing Assumptions'!$C$30/12 -> 4438.2506 | K36: =+'Loan Amortization'!$C$28*'Financing Assumptions'!$C$30/12 -> 4438.2506 | ... O36: =+'Loan Amortization'!$C$28*'Financing Assumptions'!$C$30/12 -> 4438.2506 | P36: =SUM(D36:O36) -> 53259.007
A37: Trustee Fee | D37: =+'Financing Assumptions'!$C$31/12 -> 416.66667 | E37: =+'Financing Assumptions'!$C$31/12 -> 416.66667 | F37: =+'Financing Assumptions'!$C$31/12 -> 416.66667 | G37: =+'Financing Assumptions'!$C$31/12 -> 416.66667 | H37: =+'Financing Assumptions'!$C$31/12 -> 416.66667 | I37: =+'Financing Assumptions'!$C$31/12 -> 416.66667 | J37: =+'Financing Assumptions'!$C$31/12 -> 416.66667 | K37: =+'Financing Assumptions'!$C$31/12 -> 416.66667 | ... O37: =+'Financing Assumptions'!$C$31/12 -> 416.66667 | P37: =SUM(D37:O37) -> 5000
A38: Servicing Fee | D38: =+'Loan Amortization'!$C$28*'Financing Assumptions'!$C$32/12 -> 2219.1253 | E38: =+'Loan Amortization'!$C$28*'Financing Assumptions'!$C$32/12 -> 2219.1253 | F38: =+'Loan Amortization'!$C$28*'Financing Assumptions'!$C$32/12 -> 2219.1253 | G38: =+'Loan Amortization'!$C$28*'Financing Assumptions'!$C$32/12 -> 2219.1253 | H38: =+'Loan Amortization'!$C$28*'Financing Assumptions'!$C$32/12 -> 2219.1253 | I38: =+'Loan Amortization'!$C$28*'Financing Assumptions'!$C$32/12 -> 2219.1253 | J38: =+'Loan Amortization'!$C$28*'Financing Assumptions'!$C$32/12 -> 2219.1253 | K38: =+'Loan Amortization'!$C$28*'Financing Assumptions'!$C$32/12 -> 2219.1253 | ... O38: =+'Loan Amortization'!$C$28*'Financing Assumptions'!$C$32/12 -> 2219.1253 | P38: =SUM(D38:O38) -> 26629.504
A39: Asset Management Fee - 10% | D39: =IF((0.1*D33)<=0,0,0.1*D33) -> 0 | E39: =IF((0.1*E33)<=0,0,0.1*E33) -> 0 | F39: =IF((0.1*F33)<=0,0,0.1*F33) -> 0 | G39: =IF((0.1*G33)<=0,0,0.1*G33) -> 0 | H39: =IF((0.1*H33)<=0,0,0.1*H33) -> 0 | I39: =IF((0.1*I33)<=0,0,0.1*I33) -> 0 | J39: =IF((0.1*J33)<=0,0,0.1*J33) -> 0 | K39: =IF((0.1*K33)<=0,0,0.1*K33) -> 1374.5475 | ... O39: =IF((0.1*O33)<=0,0,0.1*O33) -> 3121.9118 | P39: =SUM(D39:O39) -> 13941.162
A41: Cash Available after Fees | D41: =+D33-SUM(D36:D40) -> -189137.12 | E41: =+E33-SUM(E36:E40) -> -161164.47 | F41: =+F33-SUM(F36:F40) -> -133191.82 | G41: =+G33-SUM(G36:G40) -> -105219.17 | H41: =+H33-SUM(H36:H40) -> -77246.518 | I41: =+I33-SUM(I36:I40) -> -49273.868 | J41: =+J33-SUM(J36:J40) -> -21301.218 | K41: =+K33-SUM(K36:K40) -> 5296.8847 | ... O41: =+O33-SUM(O36:O40) -> 21023.164 | P41: =SUM(D41:O41) -> -646433.93
A43: RATIOS & ASSUMPTIONS
A45: Senior A Bond DSCR | D45: =IF((D30+D31)=0,"N/A",D26/(D30+D31)) -> -0.39609805 | E45: =IF((E30+E31)=0,"N/A",E26/(E30+E31)) -> -0.16691152 | F45: =IF((F30+F31)=0,"N/A",F26/(F30+F31)) -> 0.062275014 | G45: =IF((G30+G31)=0,"N/A",G26/(G30+G31)) -> 0.29146155 | H45: =IF((H30+H31)=0,"N/A",H26/(H30+H31)) -> 0.52064808 | I45: =IF((I30+I31)=0,"N/A",I26/(I30+I31)) -> 0.74983461 | J45: =IF((J30+J31)=0,"N/A",J26/(J30+J31)) -> 0.97902115 | K45: =IF((K30+K31)=0,"N/A",K26/(K30+K31)) -> 1.2082077 | ... P45: =IF((P30+P31)=0,"N/A",P26/(P30+P31)) -> 0.72170017
A47: Revenue Growth Rate | D47: N/A | E47: =E12/D12-1 -> 1 | F47: =F12/E12-1 -> 0.5 | G47: =G12/F12-1 -> 0.33333333 | H47: =H12/G12-1 -> 0.25 | I47: =I12/H12-1 -> 0.2 | J47: =J12/I12-1 -> 0.16666667 | K47: =K12/J12-1 -> 0.14285714 | L47: =L12/K12-1 -> 0.085 | ... O47: =O12/N12-1 -> 0 | P47: N/A
A48: Expense Growth Rate | D48: N/A | E48: =E24/D24-1 -> 0.043484624 | F48: =F24/E24-1 -> 0.04167251 | G48: =G24/F24-1 -> 0.040005385 | H48: =H24/G24-1 -> 0.038466517 | I48: =I24/H24-1 -> 0.037041654 | J48: =J24/I24-1 -> 0.035718579 | K48: =K24/J24-1 -> 0.034486761 | L48: =L24/K24-1 -> 0.029953375 | ... O48: =O24/N24-1 -> 0 | P48: N/A
A49: Expenses as a % of Gross Revenues | D49: =D24/D9 -> 0.27188257 | E49: =E24/E9 -> 0.28370528 | F49: =F24/F9 -> 0.29552799 | G49: =G24/G9 -> 0.30735071 | H49: =H24/H9 -> 0.31917342 | I49: =I24/I9 -> 0.33099613 | J49: =J24/J9 -> 0.34281884 | K49: =K24/K9 -> 0.35464155 | ... P49: =P24/P9 -> 0.33126885
A50: NOI as a % of Gross Revenues | D50: =+D26/D9 -> -0.16473971 | E50: =+E26/E9 -> -0.069419569 | F50: =+F26/F9 -> 0.025900577 | G50: =+G26/G9 -> 0.12122072 | H50: =+H26/H9 -> 0.21654087 | I50: =+I26/I9 -> 0.31186101 | J50: =+J26/J9 -> 0.40718116 | K50: =+K26/K9 -> 0.50250131 | ... P50: =+P26/P9 -> 0.30015972
A52: LEASE-UP ASSUMPTIONS
A53: Units Leased per Month | D53: 30 | E53: =D53 -> 30 | F53: =E53 -> 30 | G53: =F53 -> 30 | H53: =G53 -> 30 | I53: =H53 -> 30 | J53: =I53 -> 30 | K53: =J53 -> 30 | L53: =K53 -> 30 | M53: 10 | N53: 0 | O53: 0 | P53: =SUM(D53:O53) -> 280
A54: Cumulative Units Occupied | D54: =MIN(SUM($D$53:D53),'Unit Mix+Rents'!$D$14) -> 30 | E54: =D53+E53 -> 60 | F54: =E54+F53 -> 90 | G54: =F54+G53 -> 120 | H54: =G54+H53 -> 150 | I54: =H54+I53 -> 180 | J54: =I54+J53 -> 210 | K54: =J54+K53 -> 240 | L54: =K54+L53 -> 270 | M54: =L54+M53 -> 280 | ... O54: =N54+O53 -> 280
